Workbook

Sheet Sheet1
A1: age | B1: 1850 | C1: 1860 | D1: 1870 | E1: 1880 | F1: 1900 | G1: 1910 | H1: 1920 | I1: 1930 | J1: 1940 | K1: 1950 | L1: 1960 | M1: 1970 | N1: 1980 | O1: 1990 | P1: 2000 | Q1: 2001 | R1: 2002 | S1: 2003 | T1: 2004 | U1: 2005 | V1: 2006 | W1: 2007 | X1: 2008 | Y1: 2009 | Z1: 2010 | AA1: 2011 | AB1: 2012 | AC1: 2013 | AD1: 2014 | AE1: 2015 | AF1: 2016 | AG1: 2017 | AH1: 2018 | AI1: 2019
A3: 0 | B3: 5272 | C3: 8270 | D3: 10990 | E3: 173116 | F3: 97805 | G3: 22469 | H3: 22791 | I3: 108555 | J3: 19179 | K3: 46309 | L3: 208527 | M3: 69195 | N3: 178418 | O3: 162420 | P3: 190378 | Q3: 13834 | R3: 12248 | S3: 14245 | T3: 14609 | U3: 34775 | V3: 34918 | W3: 34916 | X3: 35122 | Y3: 34150 | Z3: 33092 | AA3: 31778 | AB3: 31250 | AC3: 31597 | AD3: 31366 | AE3: 31078 | AF3: 31106 | AG3: 31127 | AH3: 30440 | AI3: 29322
A4: 1 | B4: 5837 | C4: 8132 | D4: 10689 | E4: 149507 | F4: 89094 | G4: 19522 | H4: 22919 | I4: 108054 | J4: 21692 | K4: 49319 | L4: 208506 | M4: 66968 | N4: 164884 | O4: 199726 | P4: 190853 | Q4: 15136 | R4: 13365 | S4: 13756 | T4: 13829 | U4: 33535 | V4: 33148 | W4: 35453 | X4: 35666 | Y4: 35716 | Z4: 35275 | AA4: 33260 | AB4: 32477 | AC4: 32581 | AD4: 32080 | AE4: 31983 | AF4: 31904 | AG4: 32162 | AH4: 31811 | AI4: 30806
A5: 2 | B5: 6097 | C5: 8806 | D5: 11501 | E5: 171051 | F5: 92887 | G5: 21636 | H5: 22982 | I5: 116039 | J5: 23161 | K5: 54005 | L5: 206818 | M5: 65757 | N5: 162704 | O5: 192787 | P5: 189590 | Q5: 15301 | R5: 13759 | S5: 15465 | T5: 14999 | U5: 36321 | V5: 36104 | W5: 35601 | X5: 35703 | Y5: 36888 | Z5: 37062 | AA5: 34709 | AB5: 33802 | AC5: 33103 | AD5: 32678 | AE5: 32599 | AF5: 32760 | AG5: 32892 | AH5: 32896 | AI5: 32170
A6: 3 | B6: 5837 | C6: 8463 | D6: 11063 | E6: 165295 | F6: 92898 | G6: 21662 | H6: 23659 | I6: 119630 | J6: 22381 | K6: 55691 | L6: 202002 | M6: 68262 | N6: 160295 | O6: 186759 | P6: 191523 | Q6: 15341 | R6: 13654 | S6: 15170 | T6: 15319 | U6: 35926 | V6: 36154 | W6: 36372 | X6: 36206 | Y6: 36391 | Z6: 37336 | AA6: 36359 | AB6: 35219 | AC6: 34564 | AD6: 33487 | AE6: 32889 | AF6: 33035 | AG6: 33649 | AH6: 33414 | AI6: 33094
A7: 4 | B7: 6003 | C7: 8275 | D7: 10662 | E7: 167697 | F7: 92999 | G7: 21199 | H7: 22766 | I7: 117719 | J7: 22808 | K7: 44371 | L7: 200110 | M7: 71601 | N7: 159187 | O7: 188480 | P7: 197253 | Q7: 15298 | R7: 13812 | S7: 15583 | T7: 15489 | U7: 36932 | V7: 36185 | W7: 36598 | X7: 36428 | Y7: 36833 | Z7: 37184 | AA7: 36816 | AB7: 36339 | AC7: 35774 | AD7: 34506 | AE7: 33410 | AF7: 33308 | AG7: 33836 | AH7: 33766 | AI7: 33656
A8: 5 | B8: 5814 | C8: 7663 | D8: 9444 | E8: 161809 | F8: 91822 | G8: 20424 | H8: 23642 | I8: 125523 | J8: 22961 | K8: 45347 | L8: 198623 | M8: 77263 | N8: 161076 | O8: 188187 | P8: 198375 | Q8: 15701 | R8: 13997 | S8: 15412 | T8: 15557 | U8: 37918 | V8: 37636 | W8: 36838 | X8: 36831 | Y8: 37073 | Z8: 37565 | AA8: 36733 | AB8: 37341 | AC8: 37383 | AD8: 35598 | AE8: 34805 | AF8: 34294 | AG8: 34253 | AH8: 34071 | AI8: 34235
A9: 6 | B9: 5732 | C9: 7622 | D9: 9820 | E9: 164921 | F9: 92344 | G9: 20323 | H9: 23302 | I9: 125186 | J9: 22051 | K9: 46685 | L9: 192025 | M9: 81302 | N9: 157656 | O9: 184031 | P9: 200206 | Q9: 15910 | R9: 14006 | S9: 15645 | T9: 15517 | U9: 37753 | V9: 37759 | W9: 38053 | X9: 36430 | Y9: 36955 | Z9: 37350 | AA9: 36756 | AB9: 36930 | AC9: 37444 | AD9: 36775 | AE9: 35624 | AF9: 34873 | AG9: 34906 | AH9: 34701 | AI9: 33983
A10: 7 | B10: 5365 | C10: 7045 | D10: 9195 | E10: 152849 | F10: 90192 | G10: 19593 | H10: 22865 | I10: 123198 | J10: 22563 | K10: 47146 | L10: 188666 | M10: 81265 | N10: 164869 | O10: 187961 | P10: 206858 | Q10: 16339 | R10: 14408 | S10: 15835 | T10: 15950 | U10: 38196 | V10: 38079 | W10: 38175 | X10: 38008 | Y10: 37284 | Z10: 37601 | AA10: 36855 | AB10: 37065 | AC10: 37494 | AD10: 37858 | AE10: 37361 | AF10: 36120 | AG10: 35909 | AH10: 35117 | AI10: 34488
A11: 8 | B11: 5761 | C11: 7040 | D11: 10243 | E11: 155478 | F11: 90010 | G11: 19350 | H11: 22767 | I11: 129471 | J11: 23870 | K11: 43699 | L11: 181587 | M11: 83021 | N11: 172226 | O11: 181156 | P11: 211503 | Q11: 16829 | R11: 14781 | S11: 16026 | T11: 16078 | U11: 38389 | V11: 38772 | W11: 38502 | X11: 38862 | Y11: 38308 | Z11: 37905 | AA11: 36629 | AB11: 37208 | AC11: 37301 | AD11: 37405 | AE11: 37816 | AF11: 37681 | AG11: 36976 | AH11: 35799 | AI11: 35099
A12: 9 | B12: 4744 | C12: 6278 | D12: 9363 | E12: 137927 | F12: 84581 | G12: 18156 | H12: 21283 | I12: 125298 | J12: 23772 | K12: 40712 | L12: 174402 | M12: 84409 | N12: 191414 | O12: 190351 | P12: 217199 | Q12: 17220 | R12: 14946 | S12: 16613 | T12: 16390 | U12: 38961 | V12: 38811 | W12: 38605 | X12: 38482 | Y12: 38811 | Z12: 38714 | AA12: 36856 | AB12: 37116 | AC12: 37876 | AD12: 37100 | AE12: 37415 | AF12: 38010 | AG12: 38605 | AH12: 36943 | AI12: 35850
A13: 10 | B13: 5494 | C13: 7083 | D13: 10964 | E13: 152943 | F13: 88481 | G13: 18826 | H13: 22234 | I13: 124510 | J13: 24857 | K13: 40599 | L13: 175789 | M13: 85472 | N13: 188119 | O13: 188298 | P13: 216626 | Q13: 17695 | R13: 15666 | S13: 16941 | T13: 16797 | U13: 40263 | V13: 39775 | W13: 39204 | X13: 38692 | Y13: 38907 | Z13: 39381 | AA13: 38629 | AB13: 37903 | AC13: 38175 | AD13: 37922 | AE13: 37378 | AF13: 37459 | AG13: 39211 | AH13: 38423 | AI13: 37222
A14: 11 | B14: 4376 | C14: 5667 | D14: 8472 | E14: 122665 | F14: 79757 | G14: 16905 | H14: 20682 | I14: 115295 | J14: 23740 | K14: 37940 | L14: 175557 | M14: 84079 | N14: 181476 | O14: 180173 | P14: 207587 | Q14: 17862 | R14: 15875 | S14: 17355 | T14: 17127 | U14: 40336 | V14: 40037 | W14: 39379 | X14: 38217 | Y14: 38762 | Z14: 39012 | AA14: 38507 | AB14: 38510 | AC14: 38067 | AD14: 37518 | AE14: 37713 | AF14: 37660 | AG14: 38515 | AH14: 38930 | AI14: 38208
... A92: 89 | B92: 24 | C92: 15 | D92: 34 | E92: 608 | F92: 462 | G92: 156 | H92: 199 | I92: 1209 | J92: 358 | K92: 487 | L92: 4112 | M92: 2556 | N92: 10487 | O92: 15177 | P92: 21873 | Q92: 1630 | R92: 1524 | S92: 620 | T92: 349 | U92: 701 | V92: 3613 | W92: 3704 | X92: 4566 | Y92: 5196 | Z92: 5469 | AA92: 6548 | AB92: 6513 | AC92: 6439 | AD92: 6494 | AE92: 6604 | AF92: 6655 | AG92: 6466 | AH92: 6489 | AI92: 6969
A93: 90 | K93: 487 | L93: 4112 | M93: 2556 | N93: 10487 | O93: 15177 | P93: 21873 | Q93: 1630 | R93: 1524 | S93: 620 | T93: 349 | U93: 701 | V93: 3613 | W93: 3704 | X93: 4566 | Y93: 5196 | Z93: 5469 | AA93: 6548 | AB93: 6513 | AC93: 6439 | AD93: 6494 | AE93: 6604 | AF93: 6655 | AG93: 6466 | AH93: 6489 | AI93: 6969

Sheet Sheet2

Sheet Sheet3
A1: age | B1: 1850 | C1: 1860 | D1: 1870 | E1: 1880 | F1: 1900 | G1: 1910 | H1: 1920 | I1: 1930 | J1: 1940 | K1: 1950 | L1: 1960 | M1: 1970 | N1: 1980 | O1: 1990 | P1: 2000 | Q1: 2001 | R1: 2002 | S1: 2003 | T1: 2004 | U1: 2005 | V1: 2006 | W1: 2007 | X1: 2008 | Y1: 2009 | Z1: 2010 | AA1: 2011 | AB1: 2012 | AC1: 2013 | AD1: 2014 | AE1: 2015 | AF1: 2016 | AG1: 2017 | AH1: 2018 | AI1: 2019
A3: 18 | B3: =Sheet1!B21/SUM(Sheet1!B$21:B$92) -> 0.044900874 | C3: =Sheet1!C21/SUM(Sheet1!C$21:C$92) -> 0.043537471 | D3: =Sheet1!D21/SUM(Sheet1!D$21:D$92) -> 0.042466274 | E3: =Sheet1!E21/SUM(Sheet1!E$21:E$92) -> 0.040858071 | F3: =Sheet1!F21/SUM(Sheet1!F$21:F$92) -> 0.03417381 | G3: =Sheet1!G21/SUM(Sheet1!G$21:G$92) -> 0.033971903 | H3: =Sheet1!H21/SUM(Sheet1!H$21:H$92) -> 0.028993963 | I3: =Sheet1!I21/SUM(Sheet1!I$21:I$92) -> 0.029707068 | J3: =Sheet1!J21/SUM(Sheet1!J$21:J$92) -> 0.029336831 | K3: =Sheet1!K21/SUM(Sheet1!K$21:K$83) -> 0.026830544 | L3: =Sheet1!L21/SUM(Sheet1!L$21:L$83) -> 0.022022477 | M3: =Sheet1!M21/SUM(Sheet1!M$21:M$83) -> 0.028755716 | N3: =Sheet1!N21/SUM(Sheet1!N$21:N$83) -> 0.02669718 | O3: =Sheet1!O21/SUM(Sheet1!O$21:O$83) -> 0.02016779 | P3: =Sheet1!P21/SUM(Sheet1!P$21:P$83) -> 0.020178602 | Q3: =Sheet1!Q21/SUM(Sheet1!Q$21:Q$83) -> 0.016877985 | R3: =Sheet1!R21/SUM(Sheet1!R$21:R$83) -> 0.016474089 | ... AI3: =Sheet1!AI21/SUM(Sheet1!AI$21:AI$83) -> 0.018231107
A4: 19 | B4: =Sheet1!B22/SUM(Sheet1!B$21:B$92) -> 0.037604 | C4: =Sheet1!C22/SUM(Sheet1!C$21:C$92) -> 0.03525078 | D4: =Sheet1!D22/SUM(Sheet1!D$21:D$92) -> 0.033031994 | E4: =Sheet1!E22/SUM(Sheet1!E$21:E$92) -> 0.035620562 | F4: =Sheet1!F22/SUM(Sheet1!F$21:F$92) -> 0.031860599 | G4: =Sheet1!G22/SUM(Sheet1!G$21:G$92) -> 0.030883231 | H4: =Sheet1!H22/SUM(Sheet1!H$21:H$92) -> 0.028228165 | I4: =Sheet1!I22/SUM(Sheet1!I$21:I$92) -> 0.027980404 | J4: =Sheet1!J22/SUM(Sheet1!J$21:J$92) -> 0.027337677 | K4: =Sheet1!K22/SUM(Sheet1!K$21:K$83) -> 0.024143467 | L4: =Sheet1!L22/SUM(Sheet1!L$21:L$83) -> 0.020077194 | M4: =Sheet1!M22/SUM(Sheet1!M$21:M$83) -> 0.027008423 | N4: =Sheet1!N22/SUM(Sheet1!N$21:N$83) -> 0.027774987 | O4: =Sheet1!O22/SUM(Sheet1!O$21:O$83) -> 0.021611749 | P4: =Sheet1!P22/SUM(Sheet1!P$21:P$83) -> 0.019866614 | Q4: =Sheet1!Q22/SUM(Sheet1!Q$21:Q$83) -> 0.014833155 | R4: =Sheet1!R22/SUM(Sheet1!R$21:R$83) -> 0.014826552 | ... AI4: =Sheet1!AI22/SUM(Sheet1!AI$21:AI$83) -> 0.017951891
A5: 20 | B5: =Sheet1!B23/SUM(Sheet1!B$21:B$92) -> 0.04349169 | C5: =Sheet1!C23/SUM(Sheet1!C$21:C$92) -> 0.039880977 | D5: =Sheet1!D23/SUM(Sheet1!D$21:D$92) -> 0.039116455 | E5: =Sheet1!E23/SUM(Sheet1!E$21:E$92) -> 0.040468239 | F5: =Sheet1!F23/SUM(Sheet1!F$21:F$92) -> 0.033917513 | G5: =Sheet1!G23/SUM(Sheet1!G$21:G$92) -> 0.03237606 | H5: =Sheet1!H23/SUM(Sheet1!H$21:H$92) -> 0.027194946 | I5: =Sheet1!I23/SUM(Sheet1!I$21:I$92) -> 0.028054444 | J5: =Sheet1!J23/SUM(Sheet1!J$21:J$92) -> 0.026845478 | K5: =Sheet1!K23/SUM(Sheet1!K$21:K$83) -> 0.023049574 | L5: =Sheet1!L23/SUM(Sheet1!L$21:L$83) -> 0.019442716 | M5: =Sheet1!M23/SUM(Sheet1!M$21:M$83) -> 0.026005012 | N5: =Sheet1!N23/SUM(Sheet1!N$21:N$83) -> 0.027347685 | O5: =Sheet1!O23/SUM(Sheet1!O$21:O$83) -> 0.020636743 | P5: =Sheet1!P23/SUM(Sheet1!P$21:P$83) -> 0.019013018 | Q5: =Sheet1!Q23/SUM(Sheet1!Q$21:Q$83) -> 0.014910998 | R5: =Sheet1!R23/SUM(Sheet1!R$21:R$83) -> 0.01453952 | ... AI5: =Sheet1!AI23/SUM(Sheet1!AI$21:AI$83) -> 0.016004292
A6: 21 | B6: =Sheet1!B24/SUM(Sheet1!B$21:B$92) -> 0.036078992 | C6: =Sheet1!C24/SUM(Sheet1!C$21:C$92) -> 0.035679754 | D6: =Sheet1!D24/SUM(Sheet1!D$21:D$92) -> 0.035391765 | E6: =Sheet1!E24/SUM(Sheet1!E$21:E$92) -> 0.035764265 | F6: =Sheet1!F24/SUM(Sheet1!F$21:F$92) -> 0.031259085 | G6: =Sheet1!G24/SUM(Sheet1!G$21:G$92) -> 0.031658455 | H6: =Sheet1!H24/SUM(Sheet1!H$21:H$92) -> 0.027778411 | I6: =Sheet1!I24/SUM(Sheet1!I$21:I$92) -> 0.027694859 | J6: =Sheet1!J24/SUM(Sheet1!J$21:J$92) -> 0.026361951 | K6: =Sheet1!K24/SUM(Sheet1!K$21:K$83) -> 0.023614446 | L6: =Sheet1!L24/SUM(Sheet1!L$21:L$83) -> 0.019568796 | M6: =Sheet1!M24/SUM(Sheet1!M$21:M$83) -> 0.024974992 | N6: =Sheet1!N24/SUM(Sheet1!N$21:N$83) -> 0.026787398 | O6: =Sheet1!O24/SUM(Sheet1!O$21:O$83) -> 0.019607153 | P6: =Sheet1!P24/SUM(Sheet1!P$21:P$83) -> 0.017856331 | Q6: =Sheet1!Q24/SUM(Sheet1!Q$21:Q$83) -> 0.015364113 | R6: =Sheet1!R24/SUM(Sheet1!R$21:R$83) -> 0.01538517 | ... AI6: =Sheet1!AI24/SUM(Sheet1!AI$21:AI$83) -> 0.01514795
A7: 22 | B7: =Sheet1!B25/SUM(Sheet1!B$21:B$92) -> 0.040866359 | C7: =Sheet1!C25/SUM(Sheet1!C$21:C$92) -> 0.0386281 | D7: =Sheet1!D25/SUM(Sheet1!D$21:D$92) -> 0.036487545 | E7: =Sheet1!E25/SUM(Sheet1!E$21:E$92) -> 0.038021622 | F7: =Sheet1!F25/SUM(Sheet1!F$21:F$92) -> 0.032900171 | G7: =Sheet1!G25/SUM(Sheet1!G$21:G$92) -> 0.031902895 | H7: =Sheet1!H25/SUM(Sheet1!H$21:H$92) -> 0.028592831 | I7: =Sheet1!I25/SUM(Sheet1!I$21:I$92) -> 0.0278159 | J7: =Sheet1!J25/SUM(Sheet1!J$21:J$92) -> 0.02536671 | K7: =Sheet1!K25/SUM(Sheet1!K$21:K$83) -> 0.023732492 | L7: =Sheet1!L25/SUM(Sheet1!L$21:L$83) -> 0.019060398 | M7: =Sheet1!M25/SUM(Sheet1!M$21:M$83) -> 0.026061314 | N7: =Sheet1!N25/SUM(Sheet1!N$21:N$83) -> 0.026784108 | O7: =Sheet1!O25/SUM(Sheet1!O$21:O$83) -> 0.018785588 | P7: =Sheet1!P25/SUM(Sheet1!P$21:P$83) -> 0.017364506 | Q7: =Sheet1!Q25/SUM(Sheet1!Q$21:Q$83) -> 0.014951662 | R7: =Sheet1!R25/SUM(Sheet1!R$21:R$83) -> 0.015297644 | ... AI7: =Sheet1!AI25/SUM(Sheet1!AI$21:AI$83) -> 0.014348914
A8: 23 | B8: =Sheet1!B26/SUM(Sheet1!B$21:B$92) -> 0.037353049 | C8: =Sheet1!C26/SUM(Sheet1!C$21:C$92) -> 0.035148643 | D8: =Sheet1!D26/SUM(Sheet1!D$21:D$92) -> 0.033916307 | E8: =Sheet1!E26/SUM(Sheet1!E$21:E$92) -> 0.0344954 | F8: =Sheet1!F26/SUM(Sheet1!F$21:F$92) -> 0.032041489 | G8: =Sheet1!G26/SUM(Sheet1!G$21:G$92) -> 0.031143385 | H8: =Sheet1!H26/SUM(Sheet1!H$21:H$92) -> 0.028439367 | I8: =Sheet1!I26/SUM(Sheet1!I$21:I$92) -> 0.026810174 | J8: =Sheet1!J26/SUM(Sheet1!J$21:J$92) -> 0.024999187 | K8: =Sheet1!K26/SUM(Sheet1!K$21:K$83) -> 0.023530502 | L8: =Sheet1!L26/SUM(Sheet1!L$21:L$83) -> 0.01859651 | M8: =Sheet1!M26/SUM(Sheet1!M$21:M$83) -> 0.026066327 | N8: =Sheet1!N26/SUM(Sheet1!N$21:N$83) -> 0.026324414 | O8: =Sheet1!O26/SUM(Sheet1!O$21:O$83) -> 0.019379401 | P8: =Sheet1!P26/SUM(Sheet1!P$21:P$83) -> 0.017070511 | Q8: =Sheet1!Q26/SUM(Sheet1!Q$21:Q$83) -> 0.01497606 | R8: =Sheet1!R26/SUM(Sheet1!R$21:R$83) -> 0.015008038 | ... AI8: =Sheet1!AI26/SUM(Sheet1!AI$21:AI$83) -> 0.014324122
A9: 24 | B9: =Sheet1!B27/SUM(Sheet1!B$21:B$92) -> 0.035258576 | C9: =Sheet1!C27/SUM(Sheet1!C$21:C$92) -> 0.03525078 | D9: =Sheet1!D27/SUM(Sheet1!D$21:D$92) -> 0.032599449 | E9: =Sheet1!E27/SUM(Sheet1!E$21:E$92) -> 0.033996415 | F9: =Sheet1!F27/SUM(Sheet1!F$21:F$92) -> 0.032328297 | G9: =Sheet1!G27/SUM(Sheet1!G$21:G$92) -> 0.031368619 | H9: =Sheet1!H27/SUM(Sheet1!H$21:H$92) -> 0.028620181 | I9: =Sheet1!I27/SUM(Sheet1!I$21:I$92) -> 0.026411927 | J9: =Sheet1!J27/SUM(Sheet1!J$21:J$92) -> 0.025054478 | K9: =Sheet1!K27/SUM(Sheet1!K$21:K$83) -> 0.023717627 | L9: =Sheet1!L27/SUM(Sheet1!L$21:L$83) -> 0.018905946 | M9: =Sheet1!M27/SUM(Sheet1!M$21:M$83) -> 0.020625077 | N9: =Sheet1!N27/SUM(Sheet1!N$21:N$83) -> 0.026166121 | O9: =Sheet1!O27/SUM(Sheet1!O$21:O$83) -> 0.019856425 | P9: =Sheet1!P27/SUM(Sheet1!P$21:P$83) -> 0.01690547 | Q9: =Sheet1!Q27/SUM(Sheet1!Q$21:Q$83) -> 0.015113157 | R9: =Sheet1!R27/SUM(Sheet1!R$21:R$83) -> 0.014888334 | ... AI9: =Sheet1!AI27/SUM(Sheet1!AI$21:AI$83) -> 0.01446881
A10: 25 | B10: =Sheet1!B28/SUM(Sheet1!B$21:B$92) -> 0.041937726 | C10: =Sheet1!C28/SUM(Sheet1!C$21:C$92) -> 0.040343996 | D10: =Sheet1!D28/SUM(Sheet1!D$21:D$92) -> 0.03897708 | E10: =Sheet1!E28/SUM(Sheet1!E$21:E$92) -> 0.038317283 | F10: =Sheet1!F28/SUM(Sheet1!F$21:F$92) -> 0.032709692 | G10: =Sheet1!G28/SUM(Sheet1!G$21:G$92) -> 0.031827817 | H10: =Sheet1!H28/SUM(Sheet1!H$21:H$92) -> 0.028977249 | I10: =Sheet1!I28/SUM(Sheet1!I$21:I$92) -> 0.026218362 | J10: =Sheet1!J28/SUM(Sheet1!J$21:J$92) -> 0.025261549 | K10: =Sheet1!K28/SUM(Sheet1!K$21:K$83) -> 0.025234737 | L10: =Sheet1!L28/SUM(Sheet1!L$21:L$83) -> 0.019276383 | M10: =Sheet1!M28/SUM(Sheet1!M$21:M$83) -> 0.021036159 | N10: =Sheet1!N28/SUM(Sheet1!N$21:N$83) -> 0.025842829 | O10: =Sheet1!O28/SUM(Sheet1!O$21:O$83) -> 0.021738738 | P10: =Sheet1!P28/SUM(Sheet1!P$21:P$83) -> 0.017165377 | Q10: =Sheet1!Q28/SUM(Sheet1!Q$21:Q$83) -> 0.015398969 | R10: =Sheet1!R28/SUM(Sheet1!R$21:R$83) -> 0.015001602 | ... AI10: =Sheet1!AI28/SUM(Sheet1!AI$21:AI$83) -> 0.014923602
A11: 26 | B11: =Sheet1!B29/SUM(Sheet1!B$21:B$92) -> 0.033579136 | C11: =Sheet1!C29/SUM(Sheet1!C$21:C$92) -> 0.033119527 | D11: =Sheet1!D29/SUM(Sheet1!D$21:D$92) -> 0.030047436 | E11: =Sheet1!E29/SUM(Sheet1!E$21:E$92) -> 0.030123471 | F11: =Sheet1!F29/SUM(Sheet1!F$21:F$92) -> 0.02913461 | G11: =Sheet1!G29/SUM(Sheet1!G$21:G$92) -> 0.029558018 | H11: =Sheet1!H29/SUM(Sheet1!H$21:H$92) -> 0.027953147 | I11: =Sheet1!I29/SUM(Sheet1!I$21:I$92) -> 0.024997846 | J11: =Sheet1!J29/SUM(Sheet1!J$21:J$92) -> 0.024569867 | K11: =Sheet1!K29/SUM(Sheet1!K$21:K$83) -> 0.024720581 | L11: =Sheet1!L29/SUM(Sheet1!L$21:L$83) -> 0.018374141 | M11: =Sheet1!M29/SUM(Sheet1!M$21:M$83) -> 0.021558303 | N11: =Sheet1!N29/SUM(Sheet1!N$21:N$83) -> 0.025054403 | O11: =Sheet1!O29/SUM(Sheet1!O$21:O$83) -> 0.02215165 | P11: =Sheet1!P29/SUM(Sheet1!P$21:P$83) -> 0.016885777 | Q11: =Sheet1!Q29/SUM(Sheet1!Q$21:Q$83) -> 0.01562785 | R11: =Sheet1!R29/SUM(Sheet1!R$21:R$83) -> 0.015026058 | ... AI11: =Sheet1!AI29/SUM(Sheet1!AI$21:AI$83) -> 0.015014235
A12: 27 | B12: =Sheet1!B30/SUM(Sheet1!B$21:B$92) -> 0.027894137 | C12: =Sheet1!C30/SUM(Sheet1!C$21:C$92) -> 0.028843404 | D12: =Sheet1!D30/SUM(Sheet1!D$21:D$92) -> 0.026784127 | E12: =Sheet1!E30/SUM(Sheet1!E$21:E$92) -> 0.026477701 | F12: =Sheet1!F30/SUM(Sheet1!F$21:F$92) -> 0.028505636 | G12: =Sheet1!G30/SUM(Sheet1!G$21:G$92) -> 0.027267267 | H12: =Sheet1!H30/SUM(Sheet1!H$21:H$92) -> 0.026816605 | I12: =Sheet1!I30/SUM(Sheet1!I$21:I$92) -> 0.023564055 | J12: =Sheet1!J30/SUM(Sheet1!J$21:J$92) -> 0.023791455 | K12: =Sheet1!K30/SUM(Sheet1!K$21:K$83) -> 0.024610404 | L12: =Sheet1!L30/SUM(Sheet1!L$21:L$83) -> 0.019387213 | M12: =Sheet1!M30/SUM(Sheet1!M$21:M$83) -> 0.022212333 | N12: =Sheet1!N30/SUM(Sheet1!N$21:N$83) -> 0.024785267 | O12: =Sheet1!O30/SUM(Sheet1!O$21:O$83) -> 0.022662858 | P12: =Sheet1!P30/SUM(Sheet1!P$21:P$83) -> 0.018006777 | Q12: =Sheet1!Q30/SUM(Sheet1!Q$21:Q$83) -> 0.015354819 | R12: =Sheet1!R30/SUM(Sheet1!R$21:R$83) -> 0.015287347 | ... AI12: =Sheet1!AI30/SUM(Sheet1!AI$21:AI$83) -> 0.015396277
A13: 28 | B13: =Sheet1!B31/SUM(Sheet1!B$21:B$92) -> 0.033463313 | C13: =Sheet1!C31/SUM(Sheet1!C$21:C$92) -> 0.033664256 | D13: =Sheet1!D31/SUM(Sheet1!D$21:D$92) -> 0.031191276 | E13: =Sheet1!E31/SUM(Sheet1!E$21:E$92) -> 0.030539598 | F13: =Sheet1!F31/SUM(Sheet1!F$21:F$92) -> 0.029339473 | G13: =Sheet1!G31/SUM(Sheet1!G$21:G$92) -> 0.030457207 | H13: =Sheet1!H31/SUM(Sheet1!H$21:H$92) -> 0.028468237 | I13: =Sheet1!I31/SUM(Sheet1!I$21:I$92) -> 0.024646094 | J13: =Sheet1!J31/SUM(Sheet1!J$21:J$92) -> 0.024102603 | K13: =Sheet1!K31/SUM(Sheet1!K$21:K$83) -> 0.026045319 | L13: =Sheet1!L31/SUM(Sheet1!L$21:L$83) -> 0.019184528 | M13: =Sheet1!M31/SUM(Sheet1!M$21:M$83) -> 0.01982335 | N13: =Sheet1!N31/SUM(Sheet1!N$21:N$83) -> 0.023598768 | O13: =Sheet1!O31/SUM(Sheet1!O$21:O$83) -> 0.022580926 | P13: =Sheet1!P31/SUM(Sheet1!P$21:P$83) -> 0.018769805 | Q13: =Sheet1!Q31/SUM(Sheet1!Q$21:Q$83) -> 0.016084452 | R13: =Sheet1!R31/SUM(Sheet1!R$21:R$83) -> 0.015324674 | ... AI13: =Sheet1!AI31/SUM(Sheet1!AI$21:AI$83) -> 0.015931135
A14: 29 | B14: =Sheet1!B32/SUM(Sheet1!B$21:B$92) -> 0.02187132 | C14: =Sheet1!C32/SUM(Sheet1!C$21:C$92) -> 0.022381555 | D14: =Sheet1!D32/SUM(Sheet1!D$21:D$92) -> 0.020473781 | E14: =Sheet1!E32/SUM(Sheet1!E$21:E$92) -> 0.021379614 | F14: =Sheet1!F32/SUM(Sheet1!F$21:F$92) -> 0.025422661 | G14: =Sheet1!G32/SUM(Sheet1!G$21:G$92) -> 0.024786202 | H14: =Sheet1!H32/SUM(Sheet1!H$21:H$92) -> 0.024493381 | I14: =Sheet1!I32/SUM(Sheet1!I$21:I$92) -> 0.024106843 | J14: =Sheet1!J32/SUM(Sheet1!J$21:J$92) -> 0.023542103 | K14: =Sheet1!K32/SUM(Sheet1!K$21:K$83) -> 0.025155165 | L14: =Sheet1!L32/SUM(Sheet1!L$21:L$83) -> 0.02017366 | M14: =Sheet1!M32/SUM(Sheet1!M$21:M$83) -> 0.018684968 | N14: =Sheet1!N32/SUM(Sheet1!N$21:N$83) -> 0.023696452 | O14: =Sheet1!O32/SUM(Sheet1!O$21:O$83) -> 0.024032507 | P14: =Sheet1!P32/SUM(Sheet1!P$21:P$83) -> 0.020049448 | Q14: =Sheet1!Q32/SUM(Sheet1!Q$21:Q$83) -> 0.016854748 | R14: =Sheet1!R32/SUM(Sheet1!R$21:R$83) -> 0.015585963 | ... AI14: =Sheet1!AI32/SUM(Sheet1!AI$21:AI$83) -> 0.016178243
... A65: 80 | B65: =Sheet1!B83/SUM(Sheet1!B$21:B$92) -> 0.0016601355 | C65: =Sheet1!C83/SUM(Sheet1!C$21:C$92) -> 0.0015660961 | D65: =Sheet1!D83/SUM(Sheet1!D$21:D$92) -> 0.0019080026 | E65: =Sheet1!E83/SUM(Sheet1!E$21:E$92) -> 0.0025065438 | F65: =Sheet1!F83/SUM(Sheet1!F$21:F$92) -> 0.0019958914 | G65: =Sheet1!G83/SUM(Sheet1!G$21:G$92) -> 0.001861235 | H65: =Sheet1!H83/SUM(Sheet1!H$21:H$92) -> 0.0018734701 | I65: =Sheet1!I83/SUM(Sheet1!I$21:I$92) -> 0.002157762 | J65: =Sheet1!J83/SUM(Sheet1!J$21:J$92) -> 0.0024978588 | K65: =Sheet1!K83/SUM(Sheet1!K$21:K$83) -> 0.0026040073 | L65: =Sheet1!L83/SUM(Sheet1!L$21:L$83) -> 0.0035887535 | M65: =Sheet1!M83/SUM(Sheet1!M$21:M$83) -> 0.0047536706 | N65: =Sheet1!N83/SUM(Sheet1!N$21:N$83) -> 0.0045909937 | O65: =Sheet1!O83/SUM(Sheet1!O$21:O$83) -> 0.005735598 | P65: =Sheet1!P83/SUM(Sheet1!P$21:P$83) -> 0.0063697279 | Q65: =Sheet1!Q83/SUM(Sheet1!Q$21:Q$83) -> 0.0072881945 | R65: =Sheet1!R83/SUM(Sheet1!R$21:R$83) -> 0.0073045126 | ... AI65: =Sheet1!AI83/SUM(Sheet1!AI$21:AI$83) -> 0.0076225429

Sheet Sheet5
A1: age | B1: 1850 | C1: 1860 | D1: 1870 | E1: 1880 | F1: 1900 | G1: 1910 | H1: 1920 | I1: 1930 | J1: 1940 | K1: 1950 | L1: 1960 | M1: 1970 | N1: 1980 | O1: 1990 | P1: 2000 | Q1: 2001 | R1: 2002 | S1: 2003 | T1: 2004 | U1: 2005 | V1: 2006 | W1: 2007 | X1: 2008 | Y1: 2009 | Z1: 2010 | AA1: 2011 | AB1: 2012 | AC1: 2013 | AD1: 2014 | AE1: 2015 | AF1: 2016 | AG1: 2017 | AH1: 2018 | AI1: 2019
A3: 25 | B3: =Sheet1!B28/SUM(Sheet1!B$28:B$92) -> 0.057889337 | C3: =Sheet1!C28/SUM(Sheet1!C$28:C$92) -> 0.054768816 | D3: =Sheet1!D28/SUM(Sheet1!D$28:D$92) -> 0.052178836 | E3: =Sheet1!E28/SUM(Sheet1!E$28:E$92) -> 0.05172591 | F3: =Sheet1!F28/SUM(Sheet1!F$28:F$92) -> 0.042396481 | G3: =Sheet1!G28/SUM(Sheet1!G$28:G$92) -> 0.040978503 | H3: =Sheet1!H28/SUM(Sheet1!H$28:H$92) -> 0.036124381 | I3: =Sheet1!I28/SUM(Sheet1!I$28:I$92) -> 0.032548158 | J3: =Sheet1!J28/SUM(Sheet1!J$28:J$92) -> 0.031007267 | K3: =Sheet1!K28/SUM(Sheet1!K$28:K$83) -> 0.030352782 | L3: =Sheet1!L28/SUM(Sheet1!L$28:L$83) -> 0.022353941 | M3: =Sheet1!M28/SUM(Sheet1!M$28:M$83) -> 0.025638121 | N3: =Sheet1!N28/SUM(Sheet1!N$28:N$83) -> 0.031821516 | O3: =Sheet1!O28/SUM(Sheet1!O$28:O$83) -> 0.025278921 | P3: =Sheet1!P28/SUM(Sheet1!P$28:P$83) -> 0.019690825 | Q3: =Sheet1!Q28/SUM(Sheet1!Q$28:Q$83) -> 0.01724461 | R3: =Sheet1!R28/SUM(Sheet1!R$28:R$83) -> 0.016788191 | ... AI3: =Sheet1!AI28/SUM(Sheet1!AI$28:AI$83) -> 0.016777085
A4: 26 | B4: =Sheet1!B29/SUM(Sheet1!B$28:B$92) -> 0.04635144 | C4: =Sheet1!C29/SUM(Sheet1!C$28:C$92) -> 0.044961269 | D4: =Sheet1!D29/SUM(Sheet1!D$28:D$92) -> 0.040224671 | E4: =Sheet1!E29/SUM(Sheet1!E$28:E$92) -> 0.040664782 | F4: =Sheet1!F29/SUM(Sheet1!F$28:F$92) -> 0.037762658 | G4: =Sheet1!G29/SUM(Sheet1!G$28:G$92) -> 0.038056123 | H4: =Sheet1!H29/SUM(Sheet1!H$28:H$92) -> 0.034847687 | I4: =Sheet1!I29/SUM(Sheet1!I$28:I$92) -> 0.031032977 | J4: =Sheet1!J29/SUM(Sheet1!J$28:J$92) -> 0.030158263 | K4: =Sheet1!K29/SUM(Sheet1!K$28:K$83) -> 0.029734346 | L4: =Sheet1!L29/SUM(Sheet1!L$28:L$83) -> 0.021307652 | M4: =Sheet1!M29/SUM(Sheet1!M$28:M$83) -> 0.026274492 | N4: =Sheet1!N29/SUM(Sheet1!N$28:N$83) -> 0.030850689 | O4: =Sheet1!O29/SUM(Sheet1!O$28:O$83) -> 0.025759076 | P4: =Sheet1!P29/SUM(Sheet1!P$28:P$83) -> 0.019370089 | Q4: =Sheet1!Q29/SUM(Sheet1!Q$28:Q$83) -> 0.017500924 | R4: =Sheet1!R29/SUM(Sheet1!R$28:R$83) -> 0.016815559 | ... AI4: =Sheet1!AI29/SUM(Sheet1!AI$28:AI$83) -> 0.016878975
A5: 27 | B5: =Sheet1!B30/SUM(Sheet1!B$28:B$92) -> 0.03850407 | C5: =Sheet1!C30/SUM(Sheet1!C$28:C$92) -> 0.039156237 | D5: =Sheet1!D30/SUM(Sheet1!D$28:D$92) -> 0.035856061 | E5: =Sheet1!E30/SUM(Sheet1!E$28:E$92) -> 0.035743222 | F5: =Sheet1!F30/SUM(Sheet1!F$28:F$92) -> 0.036947417 | G5: =Sheet1!G30/SUM(Sheet1!G$28:G$92) -> 0.035106768 | H5: =Sheet1!H30/SUM(Sheet1!H$28:H$92) -> 0.033430822 | I5: =Sheet1!I30/SUM(Sheet1!I$28:I$92) -> 0.029253031 | J5: =Sheet1!J30/SUM(Sheet1!J$28:J$92) -> 0.029202801 | K5: =Sheet1!K30/SUM(Sheet1!K$28:K$83) -> 0.029601824 | L5: =Sheet1!L30/SUM(Sheet1!L$28:L$83) -> 0.022482465 | M5: =Sheet1!M30/SUM(Sheet1!M$28:M$83) -> 0.0270716 | N5: =Sheet1!N30/SUM(Sheet1!N$28:N$83) -> 0.030519289 | O5: =Sheet1!O30/SUM(Sheet1!O$28:O$83) -> 0.026353535 | P5: =Sheet1!P30/SUM(Sheet1!P$28:P$83) -> 0.020656015 | Q5: =Sheet1!Q30/SUM(Sheet1!Q$28:Q$83) -> 0.017195168 | R5: =Sheet1!R30/SUM(Sheet1!R$28:R$83) -> 0.017107966 | ... AI5: =Sheet1!AI30/SUM(Sheet1!AI$28:AI$83) -> 0.017308466
A6: 28 | B6: =Sheet1!B31/SUM(Sheet1!B$28:B$92) -> 0.046191561 | C6: =Sheet1!C31/SUM(Sheet1!C$28:C$92) -> 0.045700764 | D6: =Sheet1!D31/SUM(Sheet1!D$28:D$92) -> 0.041755937 | E6: =Sheet1!E31/SUM(Sheet1!E$28:E$92) -> 0.041226527 | F6: =Sheet1!F31/SUM(Sheet1!F$28:F$92) -> 0.03802819 | G6: =Sheet1!G31/SUM(Sheet1!G$28:G$92) -> 0.039213835 | H6: =Sheet1!H31/SUM(Sheet1!H$28:H$92) -> 0.035489822 | I6: =Sheet1!I31/SUM(Sheet1!I$28:I$92) -> 0.030596304 | J6: =Sheet1!J31/SUM(Sheet1!J$28:J$92) -> 0.02958472 | K6: =Sheet1!K31/SUM(Sheet1!K$28:K$83) -> 0.031327765 | L6: =Sheet1!L31/SUM(Sheet1!L$28:L$83) -> 0.02224742 | M6: =Sheet1!M31/SUM(Sheet1!M$28:M$83) -> 0.024159993 | N6: =Sheet1!N31/SUM(Sheet1!N$28:N$83) -> 0.029058296 | O6: =Sheet1!O31/SUM(Sheet1!O$28:O$83) -> 0.02625826 | P6: =Sheet1!P31/SUM(Sheet1!P$28:P$83) -> 0.021531303 | Q6: =Sheet1!Q31/SUM(Sheet1!Q$28:Q$83) -> 0.018012251 | R6: =Sheet1!R31/SUM(Sheet1!R$28:R$83) -> 0.017149738 | ... AI6: =Sheet1!AI31/SUM(Sheet1!AI$28:AI$83) -> 0.017909752
A7: 29 | B7: =Sheet1!B32/SUM(Sheet1!B$28:B$92) -> 0.030190389 | C7: =Sheet1!C32/SUM(Sheet1!C$28:C$92) -> 0.030383983 | D7: =Sheet1!D32/SUM(Sheet1!D$28:D$92) -> 0.027408365 | E7: =Sheet1!E32/SUM(Sheet1!E$28:E$92) -> 0.028861128 | F7: =Sheet1!F32/SUM(Sheet1!F$28:F$92) -> 0.032951438 | G7: =Sheet1!G32/SUM(Sheet1!G$28:G$92) -> 0.031912383 | H7: =Sheet1!H32/SUM(Sheet1!H$28:H$92) -> 0.030534582 | I7: =Sheet1!I32/SUM(Sheet1!I$28:I$92) -> 0.029926864 | J7: =Sheet1!J32/SUM(Sheet1!J$28:J$92) -> 0.028896734 | K7: =Sheet1!K32/SUM(Sheet1!K$28:K$83) -> 0.030257072 | L7: =Sheet1!L32/SUM(Sheet1!L$28:L$83) -> 0.023394472 | M7: =Sheet1!M32/SUM(Sheet1!M$28:M$83) -> 0.022772574 | N7: =Sheet1!N32/SUM(Sheet1!N$28:N$83) -> 0.029178578 | O7: =Sheet1!O32/SUM(Sheet1!O$28:O$83) -> 0.027946233 | P7: =Sheet1!P32/SUM(Sheet1!P$28:P$83) -> 0.022999214 | Q7: =Sheet1!Q32/SUM(Sheet1!Q$28:Q$83) -> 0.018874872 | R7: =Sheet1!R32/SUM(Sheet1!R$28:R$83) -> 0.017442145 | ... AI7: =Sheet1!AI32/SUM(Sheet1!AI$28:AI$83) -> 0.01818755
A8: 30 | B8: =Sheet1!B33/SUM(Sheet1!B$28:B$92) -> 0.063658286 | C8: =Sheet1!C33/SUM(Sheet1!C$28:C$92) -> 0.065177201 | D8: =Sheet1!D33/SUM(Sheet1!D$28:D$92) -> 0.057911431 | E8: =Sheet1!E33/SUM(Sheet1!E$28:E$92) -> 0.055450512 | F8: =Sheet1!F33/SUM(Sheet1!F$28:F$92) -> 0.041996487 | G8: =Sheet1!G33/SUM(Sheet1!G$28:G$92) -> 0.041792273 | H8: =Sheet1!H33/SUM(Sheet1!H$28:H$92) -> 0.036239928 | I8: =Sheet1!I33/SUM(Sheet1!I$28:I$92) -> 0.034195408 | J8: =Sheet1!J33/SUM(Sheet1!J$28:J$92) -> 0.031116387 | K8: =Sheet1!K33/SUM(Sheet1!K$28:K$83) -> 0.032563584 | L8: =Sheet1!L33/SUM(Sheet1!L$28:L$83) -> 0.023948462 | M8: =Sheet1!M33/SUM(Sheet1!M$28:M$83) -> 0.022833673 | N8: =Sheet1!N33/SUM(Sheet1!N$28:N$83) -> 0.028934118 | O8: =Sheet1!O33/SUM(Sheet1!O$28:O$83) -> 0.02915796 | P8: =Sheet1!P33/SUM(Sheet1!P$28:P$83) -> 0.023137622 | Q8: =Sheet1!Q33/SUM(Sheet1!Q$28:Q$83) -> 0.021440616 | R8: =Sheet1!R33/SUM(Sheet1!R$28:R$83) -> 0.019889433 | ... AI8: =Sheet1!AI33/SUM(Sheet1!AI$28:AI$83) -> 0.018535255
A9: 31 | B9: =Sheet1!B34/SUM(Sheet1!B$28:B$92) -> 0.02546065 | C9: =Sheet1!C34/SUM(Sheet1!C$28:C$92) -> 0.024273909 | D9: =Sheet1!D34/SUM(Sheet1!D$28:D$92) -> 0.02101308 | E9: =Sheet1!E34/SUM(Sheet1!E$28:E$92) -> 0.022720322 | F9: =Sheet1!F34/SUM(Sheet1!F$28:F$92) -> 0.027505764 | G9: =Sheet1!G34/SUM(Sheet1!G$28:G$92) -> 0.025721434 | H9: =Sheet1!H34/SUM(Sheet1!H$28:H$92) -> 0.026424158 | I9: =Sheet1!I34/SUM(Sheet1!I$28:I$92) -> 0.024101416 | J9: =Sheet1!J34/SUM(Sheet1!J$28:J$92) -> 0.025242558 | K9: =Sheet1!K34/SUM(Sheet1!K$28:K$83) -> 0.027911644 | L9: =Sheet1!L34/SUM(Sheet1!L$28:L$83) -> 0.023695115 | M9: =Sheet1!M34/SUM(Sheet1!M$28:M$83) -> 0.021724489 | N9: =Sheet1!N34/SUM(Sheet1!N$28:N$83) -> 0.028302169 | O9: =Sheet1!O34/SUM(Sheet1!O$28:O$83) -> 0.026622026 | P9: =Sheet1!P34/SUM(Sheet1!P$28:P$83) -> 0.022109133 | Q9: =Sheet1!Q34/SUM(Sheet1!Q$28:Q$83) -> 0.020783567 | R9: =Sheet1!R34/SUM(Sheet1!R$28:R$83) -> 0.020759451 | ... AI9: =Sheet1!AI34/SUM(Sheet1!AI$28:AI$83) -> 0.017581238
A10: 32 | B10: =Sheet1!B35/SUM(Sheet1!B$28:B$92) -> 0.034160705 | C10: =Sheet1!C35/SUM(Sheet1!C$28:C$92) -> 0.03348986 | D10: =Sheet1!D35/SUM(Sheet1!D$28:D$92) -> 0.029859677 | E10: =Sheet1!E35/SUM(Sheet1!E$28:E$92) -> 0.030646658 | F10: =Sheet1!F35/SUM(Sheet1!F$28:F$92) -> 0.031942979 | G10: =Sheet1!G35/SUM(Sheet1!G$28:G$92) -> 0.032159661 | H10: =Sheet1!H35/SUM(Sheet1!H$28:H$92) -> 0.031091479 | I10: =Sheet1!I35/SUM(Sheet1!I$28:I$92) -> 0.029445331 | J10: =Sheet1!J35/SUM(Sheet1!J$28:J$92) -> 0.028623935 | K10: =Sheet1!K35/SUM(Sheet1!K$28:K$83) -> 0.030368558 | L10: =Sheet1!L35/SUM(Sheet1!L$28:L$83) -> 0.024825922 | M10: =Sheet1!M35/SUM(Sheet1!M$28:M$83) -> 0.021195747 | N10: =Sheet1!N35/SUM(Sheet1!N$28:N$83) -> 0.029166114 | O10: =Sheet1!O35/SUM(Sheet1!O$28:O$83) -> 0.028344146 | P10: =Sheet1!P35/SUM(Sheet1!P$28:P$83) -> 0.021931392 | Q10: =Sheet1!Q35/SUM(Sheet1!Q$28:Q$83) -> 0.020339896 | R10: =Sheet1!R35/SUM(Sheet1!R$28:R$83) -> 0.020765213 | ... AI10: =Sheet1!AI35/SUM(Sheet1!AI$28:AI$83) -> 0.017791871
A11: 33 | B11: =Sheet1!B36/SUM(Sheet1!B$28:B$92) -> 0.029577521 | C11: =Sheet1!C36/SUM(Sheet1!C$28:C$92) -> 0.030263815 | D11: =Sheet1!D36/SUM(Sheet1!D$28:D$92) -> 0.026906522 | E11: =Sheet1!E36/SUM(Sheet1!E$28:E$92) -> 0.026749116 | F11: =Sheet1!F36/SUM(Sheet1!F$28:F$92) -> 0.029384264 | G11: =Sheet1!G36/SUM(Sheet1!G$28:G$92) -> 0.028250416 | H11: =Sheet1!H36/SUM(Sheet1!H$28:H$92) -> 0.028723723 | I11: =Sheet1!I36/SUM(Sheet1!I$28:I$92) -> 0.027079076 | J11: =Sheet1!J36/SUM(Sheet1!J$28:J$92) -> 0.025297118 | K11: =Sheet1!K36/SUM(Sheet1!K$28:K$83) -> 0.028845608 | L11: =Sheet1!L36/SUM(Sheet1!L$28:L$83) -> 0.024507799 | M11: =Sheet1!M36/SUM(Sheet1!M$28:M$83) -> 0.020399579 | N11: =Sheet1!N36/SUM(Sheet1!N$28:N$83) -> 0.028674234 | O11: =Sheet1!O36/SUM(Sheet1!O$28:O$83) -> 0.027802082 | P11: =Sheet1!P36/SUM(Sheet1!P$28:P$83) -> 0.022455441 | Q11: =Sheet1!Q36/SUM(Sheet1!Q$28:Q$83) -> 0.020235809 | R11: =Sheet1!R36/SUM(Sheet1!R$28:R$83) -> 0.020331644 | ... AI11: =Sheet1!AI36/SUM(Sheet1!AI$28:AI$83) -> 0.017815173
A12: 34 | B12: =Sheet1!B37/SUM(Sheet1!B$28:B$92) -> 0.027778888 | C12: =Sheet1!C37/SUM(Sheet1!C$28:C$92) -> 0.028868019 | D12: =Sheet1!D37/SUM(Sheet1!D$28:D$92) -> 0.025446029 | E12: =Sheet1!E37/SUM(Sheet1!E$28:E$92) -> 0.025584353 | F12: =Sheet1!F37/SUM(Sheet1!F$28:F$92) -> 0.028854894 | G12: =Sheet1!G37/SUM(Sheet1!G$28:G$92) -> 0.028810164 | H12: =Sheet1!H37/SUM(Sheet1!H$28:H$92) -> 0.029221899 | I12: =Sheet1!I37/SUM(Sheet1!I$28:I$92) -> 0.027531121 | J12: =Sheet1!J37/SUM(Sheet1!J$28:J$92) -> 0.026377668 | K12: =Sheet1!K37/SUM(Sheet1!K$28:K$83) -> 0.030040409 | L12: =Sheet1!L37/SUM(Sheet1!L$28:L$83) -> 0.025437697 | M12: =Sheet1!M37/SUM(Sheet1!M$28:M$83) -> 0.020754423 | N12: =Sheet1!N37/SUM(Sheet1!N$28:N$83) -> 0.022412077 | O12: =Sheet1!O37/SUM(Sheet1!O$28:O$83) -> 0.027119516 | P12: =Sheet1!P37/SUM(Sheet1!P$28:P$83) -> 0.023495168 | Q12: =Sheet1!Q37/SUM(Sheet1!Q$28:Q$83) -> 0.020674275 | R12: =Sheet1!R37/SUM(Sheet1!R$28:R$83) -> 0.020157352 | ... AI12: =Sheet1!AI37/SUM(Sheet1!AI$28:AI$83) -> 0.017851725
A13: 35 | B13: =Sheet1!B38/SUM(Sheet1!B$28:B$92) -> 0.041901488 | C13: =Sheet1!C38/SUM(Sheet1!C$28:C$92) -> 0.043750347 | D13: =Sheet1!D38/SUM(Sheet1!D$28:D$92) -> 0.046362601 | E13: =Sheet1!E38/SUM(Sheet1!E$28:E$92) -> 0.043897393 | F13: =Sheet1!F38/SUM(Sheet1!F$28:F$92) -> 0.032786468 | G13: =Sheet1!G38/SUM(Sheet1!G$28:G$92) -> 0.034960649 | H13: =Sheet1!H38/SUM(Sheet1!H$28:H$92) -> 0.033385361 | I13: =Sheet1!I38/SUM(Sheet1!I$28:I$92) -> 0.032108348 | J13: =Sheet1!J38/SUM(Sheet1!J$28:J$92) -> 0.027786908 | K13: =Sheet1!K38/SUM(Sheet1!K$28:K$83) -> 0.031206812 | L13: =Sheet1!L38/SUM(Sheet1!L$28:L$83) -> 0.02623907 | M13: =Sheet1!M38/SUM(Sheet1!M$28:M$83) -> 0.020854062 | N13: =Sheet1!N38/SUM(Sheet1!N$28:N$83) -> 0.022535164 | O13: =Sheet1!O38/SUM(Sheet1!O$28:O$83) -> 0.027642942 | P13: =Sheet1!P38/SUM(Sheet1!P$28:P$83) -> 0.025156415 | Q13: =Sheet1!Q38/SUM(Sheet1!Q$28:Q$83) -> 0.021938932 | R13: =Sheet1!R38/SUM(Sheet1!R$28:R$83) -> 0.021203103 | ... AI13: =Sheet1!AI38/SUM(Sheet1!AI$28:AI$83) -> 0.017983771
A14: 36 | B14: =Sheet1!B39/SUM(Sheet1!B$28:B$92) -> 0.027259283 | C14: =Sheet1!C39/SUM(Sheet1!C$28:C$92) -> 0.029866336 | D14: =Sheet1!D39/SUM(Sheet1!D$28:D$92) -> 0.027575646 | E14: =Sheet1!E39/SUM(Sheet1!E$28:E$92) -> 0.027277429 | F14: =Sheet1!F39/SUM(Sheet1!F$28:F$92) -> 0.026730635 | G14: =Sheet1!G39/SUM(Sheet1!G$28:G$92) -> 0.028176233 | H14: =Sheet1!H39/SUM(Sheet1!H$28:H$92) -> 0.029163178 | I14: =Sheet1!I39/SUM(Sheet1!I$28:I$92) -> 0.028153192 | J14: =Sheet1!J39/SUM(Sheet1!J$28:J$92) -> 0.025230582 | K14: =Sheet1!K39/SUM(Sheet1!K$28:K$83) -> 0.029776417 | L14: =Sheet1!L39/SUM(Sheet1!L$28:L$83) -> 0.02564642 | M14: =Sheet1!M39/SUM(Sheet1!M$28:M$83) -> 0.020185732 | N14: =Sheet1!N39/SUM(Sheet1!N$28:N$83) -> 0.022875444 | O14: =Sheet1!O39/SUM(Sheet1!O$28:O$83) -> 0.026181232 | P14: =Sheet1!P39/SUM(Sheet1!P$28:P$83) -> 0.025503984 | Q14: =Sheet1!Q39/SUM(Sheet1!Q$28:Q$83) -> 0.022932963 | R14: =Sheet1!R39/SUM(Sheet1!R$28:R$83) -> 0.021273684 | ... AI14: =Sheet1!AI39/SUM(Sheet1!AI$28:AI$83) -> 0.01778319
... A58: 80 | B58: =Sheet1!B83/SUM(Sheet1!B$28:B$92) -> 0.0022915917 | C58: =Sheet1!C83/SUM(Sheet1!C$28:C$92) -> 0.0021260468 | D58: =Sheet1!D83/SUM(Sheet1!D$28:D$92) -> 0.0025542538 | E58: =Sheet1!E83/SUM(Sheet1!E$28:E$92) -> 0.0033836757 | F58: =Sheet1!F83/SUM(Sheet1!F$28:F$92) -> 0.0025869633 | G58: =Sheet1!G83/SUM(Sheet1!G$28:G$92) -> 0.0023963511 | H58: =Sheet1!H83/SUM(Sheet1!H$28:H$92) -> 0.0023355546 | I58: =Sheet1!I83/SUM(Sheet1!I$28:I$92) -> 0.002678702 | J58: =Sheet1!J83/SUM(Sheet1!J$28:J$92) -> 0.0030659947 | K58: =Sheet1!K83/SUM(Sheet1!K$28:K$83) -> 0.0031321454 | L58: =Sheet1!L83/SUM(Sheet1!L$28:L$83) -> 0.0041617133 | M58: =Sheet1!M83/SUM(Sheet1!M$28:M$83) -> 0.0057936044 | N58: =Sheet1!N83/SUM(Sheet1!N$28:N$83) -> 0.0056531109 | O58: =Sheet1!O83/SUM(Sheet1!O$28:O$83) -> 0.0066696479 | P58: =Sheet1!P83/SUM(Sheet1!P$28:P$83) -> 0.007306871 | Q58: =Sheet1!Q83/SUM(Sheet1!Q$28:Q$83) -> 0.0081617199 | R58: =Sheet1!R83/SUM(Sheet1!R$28:R$83) -> 0.0081744301 | ... AI58: =Sheet1!AI83/SUM(Sheet1!AI$28:AI$83) -> 0.0085692485

Sheet Sheet4
A1: age | B1: 1950 | C1: 1951 | D1: 1952 | E1: 1953 | F1: 1954 | G1: 1955 | H1: 1956 | I1: 1957 | J1: 1958 | K1: 1959 | L1: 1960 | M1: 1961 | N1: 1962 | O1: 1963 | P1: 1964 | Q1: 1965 | R1: 1966 | S1: 1967 | T1: 1968 | U1: 1969 | V1: 1970 | W1: 1971 | X1: 1972 | Y1: 1973 | Z1: 1974 | AA1: 1975 | AB1: 1976 | AC1: 1977 | AD1: 1978 | AE1: 1979 | AF1: 1980 | AG1: 1981 | AH1: 1982 | AI1: 1983 | AJ1: 1984 | AK1: 1985 | AL1: 1986 | AM1: 1987 | AN1: 1988 | AO1: 1989 | AP1: 1990 | AQ1: 1991 | AR1: 1992 | AS1: 1993 | AT1: 1994 | AU1: 1995 | AV1: 1996 | AW1: 1997 | AX1: 1998 | AY1: 1999 | AZ1: 2000 | BA1: 2001 | BB1: 2002 | BC1: 2003 | BD1: 2004 | BE1: 2005 | BF1: 2006 | BG1: 2007 | BH1: 2008 | BI1: 2009 | BJ1: 2010 | BK1: 2011 | BL1: 2012 | BM1: 2013 | BN1: 2014 | BO1: 2015 | BP1: 2016 | BQ1: 2017 | BR1: 2018 | BS1: 2019
A3: 25 | B3: ='[1]1950'!$B35/SUM('[1]1950'!$B$35:$B$90) -> 0.027870384 | C3: ='[1]1951'!$B35/SUM('[1]1951'!$B$35:$B$90) -> 0.026836558 | D3: ='[1]1952'!$B35/SUM('[1]1952'!$B$35:$B$90) -> 0.02631222 | E3: ='[1]1953'!$B35/SUM('[1]1953'!$B$35:$B$90) -> 0.025865952 | F3: ='[1]1954'!$B35/SUM('[1]1954'!$B$35:$B$90) -> 0.024771584 | G3: ='[1]1955'!$B35/SUM('[1]1955'!$B$35:$B$90) -> 0.024397984 | H3: ='[1]1956'!$B35/SUM('[1]1956'!$B$35:$B$90) -> 0.02381922 | I3: ='[1]1957'!$B35/SUM('[1]1957'!$B$35:$B$90) -> 0.022697633 | J3: ='[1]1958'!$B35/SUM('[1]1958'!$B$35:$B$90) -> 0.021701182 | K3: ='[1]1959'!$B35/SUM('[1]1959'!$B$35:$B$90) -> 0.021253001 | L3: ='[2]1961'!$B35/SUM('[2]1961'!$B$35:$B$90) -> 0.022414127 | M3: ='[2]1962'!$B35/SUM('[2]1962'!$B$35:$B$90) -> 0.022239117 | N3: ='[2]1963'!$B35/SUM('[2]1963'!$B$35:$B$90) -> 0.022318917 | O3: ='[2]1964'!$B35/SUM('[2]1964'!$B$35:$B$90) -> 0.022863002 | P3: ='[2]1965'!$B35/SUM('[2]1965'!$B$35:$B$90) -> 0.02301759 | Q3: ='[2]1966'!$B35/SUM('[2]1966'!$B$35:$B$90) -> 0.023250505 | R3: ='[2]1967'!$B35/SUM('[2]1967'!$B$35:$B$90) -> 0.024368713 | S3: ='[2]1968'!$B35/SUM('[2]1968'!$B$35:$B$90) -> 0.02552218 | T3: ='[2]1969'!$B35/SUM('[2]1969'!$B$35:$B$90) -> 0.028465852 | U3: ='[2]1969'!$B35/SUM('[2]1969'!$B$35:$B$90) -> 0.028465852 | V3: ='[3]1971'!$B35/SUM('[3]1971'!$B$35:$B$90) -> 0.02604537 | W3: ='[3]1972'!$B35/SUM('[3]1972'!$B$35:$B$90) -> 0.025358792 | X3: ='[3]1973'!$B35/SUM('[3]1973'!$B$35:$B$90) -> 0.034328575 | Y3: ='[3]1974'!$B35/SUM('[3]1974'!$B$35:$B$90) -> 0.031405909 | Z3: ='[3]1975'!$B35/SUM('[3]1975'!$B$35:$B$90) -> 0.03105297 | AA3: ='[3]1976'!$B35/SUM('[3]1976'!$B$35:$B$90) -> 0.030558084 | AB3: ='[3]1977'!$B35/SUM('[3]1977'!$B$35:$B$90) -> 0.031246086 | AC3: ='[3]1978'!$B35/SUM('[3]1978'!$B$35:$B$90) -> 0.031556909 | AD3: ='[3]1979'!$B35/SUM('[3]1979'!$B$35:$B$90) -> 0.031855027 | AE3: ='[3]1979'!$B35/SUM('[3]1979'!$B$35:$B$90) -> 0.031855027 | AF3: ='[4]1980'!$D27/SUM('[4]1980'!$D$27:$D$82) -> 0.032078612 | AG3: ='[4]1981'!$D27/SUM('[4]1981'!$D$27:$D$82) -> 0.032098379 | AH3: ='[4]1982'!$D27/SUM('[4]1982'!$D$27:$D$82) -> 0.032194365 | AI3: ='[4]1983'!$D27/SUM('[4]1983'!$D$27:$D$82) -> 0.032313895 | AJ3: ='[4]1984'!$D27/SUM('[4]1984'!$D$27:$D$82) -> 0.031573941 | AK3: ='[4]1985'!$D27/SUM('[4]1985'!$D$27:$D$82) -> 0.031116014 | AL3: ='[4]1986'!$D27/SUM('[4]1986'!$D$27:$D$82) -> 0.030717644 | AM3: ='[4]1987'!$D27/SUM('[4]1987'!$D$27:$D$82) -> 0.029978043 | AN3: ='[4]1988'!$D27/SUM('[4]1988'!$D$27:$D$82) -> 0.028937452 | AO3: ='[4]1989'!$D27/SUM('[4]1989'!$D$27:$D$82) -> 0.028161153 | AP3: ='[5]us-est90int-09'!$C29/SUM('[5]us-est90int-09'!$C$29:$C$84) -> 0.02665654 | AQ3: ='[5]us-est90int-09'!$C957/SUM('[5]us-est90int-09'!$C$957:$C$1012) -> 0.025530665 | AR3: ='[5]us-est90int-09'!$C2194/SUM('[5]us-est90int-09'!$C$2194:$C$2249) -> 0.024069838 | AS3: ='[5]us-est90int-09'!$C3431/SUM('[5]us-est90int-09'!$C$3431:$C$3486) -> 0.023529666 | AT3: ='[5]us-est90int-09'!$C4668/SUM('[5]us-est90int-09'!$C$4668:$C$4723) -> 0.02347665 | AU3: ='[5]us-est90int-09'!$C5905/SUM('[5]us-est90int-09'!$C$5905:$C$5960) -> 0.023852999 | AV3: ='[5]us-est90int-09'!$C7142/SUM('[5]us-est90int-09'!$C$7142:$C$7197) -> 0.024941555 | AW3: ='[5]us-est90int-09'!$C8379/SUM('[5]us-est90int-09'!$C$8379:$C$8434) -> 0.023048304 | AX3: ='[5]us-est90int-09'!$C9616/SUM('[5]us-est90int-09'!$C$9616:$C$9671) -> 0.021938129 | AY3: ='[5]us-est90int-09'!$C10853/SUM('[5]us-est90int-09'!$C$10853:$C$10908) -> 0.021009641 | AZ3: =Sheet1!P28/SUM(Sheet1!P$28:P$83) -> 0.019690825 | BA3: =Sheet1!Q28/SUM(Sheet1!Q$28:Q$83) -> 0.01724461 | BB3: =Sheet1!R28/SUM(Sheet1!R$28:R$83) -> 0.016788191 | BC3: =Sheet1!S28/SUM(Sheet1!S$28:S$83) -> 0.017364359 | BD3: =Sheet1!T28/SUM(Sheet1!T$28:T$83) -> 0.016927364 | BE3: =Sheet1!U28/SUM(Sheet1!U$28:U$83) -> 0.017336159 | BF3: =Sheet1!V28/SUM(Sheet1!V$28:V$83) -> 0.01786211 | BG3: =Sheet1!W28/SUM(Sheet1!W$28:W$83) -> 0.017894629 | ... BS3: =Sheet1!AI28/SUM(Sheet1!AI$28:AI$83) -> 0.016777085
A4: 26 | B4: ='[1]1950'!$B36/SUM('[1]1950'!$B$35:$B$90) -> 0.02851412 | C4: ='[1]1951'!$B36/SUM('[1]1951'!$B$35:$B$90) -> 0.027999646 | D4: ='[1]1952'!$B36/SUM('[1]1952'!$B$35:$B$90) -> 0.027004062 | E4: ='[1]1953'!$B36/SUM('[1]1953'!$B$35:$B$90) -> 0.026487867 | F4: ='[1]1954'!$B36/SUM('[1]1954'!$B$35:$B$90) -> 0.026079213 | G4: ='[1]1955'!$B36/SUM('[1]1955'!$B$35:$B$90) -> 0.024996159 | H4: ='[1]1956'!$B36/SUM('[1]1956'!$B$35:$B$90) -> 0.024675754 | I4: ='[1]1957'!$B36/SUM('[1]1957'!$B$35:$B$90) -> 0.024126586 | J4: ='[1]1958'!$B36/SUM('[1]1958'!$B$35:$B$90) -> 0.02302087 | K4: ='[1]1959'!$B36/SUM('[1]1959'!$B$35:$B$90) -> 0.022020957 | L4: ='[2]1961'!$B36/SUM('[2]1961'!$B$35:$B$90) -> 0.021885637 | M4: ='[2]1962'!$B36/SUM('[2]1962'!$B$35:$B$90) -> 0.022346832 | N4: ='[2]1963'!$B36/SUM('[2]1963'!$B$35:$B$90) -> 0.022209135 | O4: ='[2]1964'!$B36/SUM('[2]1964'!$B$35:$B$90) -> 0.022295428 | P4: ='[2]1965'!$B36/SUM('[2]1965'!$B$35:$B$90) -> 0.022858433 | Q4: ='[2]1966'!$B36/SUM('[2]1966'!$B$35:$B$90) -> 0.023044044 | R4: ='[2]1967'!$B36/SUM('[2]1967'!$B$35:$B$90) -> 0.023242453 | S4: ='[2]1968'!$B36/SUM('[2]1968'!$B$35:$B$90) -> 0.0243558 | T4: ='[2]1969'!$B36/SUM('[2]1969'!$B$35:$B$90) -> 0.02543807 | U4: ='[2]1969'!$B36/SUM('[2]1969'!$B$35:$B$90) -> 0.02543807 | V4: ='[3]1971'!$B36/SUM('[3]1971'!$B$35:$B$90) -> 0.026745706 | W4: ='[3]1972'!$B36/SUM('[3]1972'!$B$35:$B$90) -> 0.026147139 | X4: ='[3]1973'!$B36/SUM('[3]1973'!$B$35:$B$90) -> 0.025205535 | Y4: ='[3]1974'!$B36/SUM('[3]1974'!$B$35:$B$90) -> 0.03416724 | Z4: ='[3]1975'!$B36/SUM('[3]1975'!$B$35:$B$90) -> 0.031279485 | AA4: ='[3]1976'!$B36/SUM('[3]1976'!$B$35:$B$90) -> 0.030906484 | AB4: ='[3]1977'!$B36/SUM('[3]1977'!$B$35:$B$90) -> 0.030366235 | AC4: ='[3]1978'!$B36/SUM('[3]1978'!$B$35:$B$90) -> 0.0310445 | AD4: ='[3]1979'!$B36/SUM('[3]1979'!$B$35:$B$90) -> 0.031313543 | AE4: ='[3]1979'!$B36/SUM('[3]1979'!$B$35:$B$90) -> 0.031313543 | AF4: ='[4]1980'!$D28/SUM('[4]1980'!$D$27:$D$82) -> 0.030997668 | AG4: ='[4]1981'!$D28/SUM('[4]1981'!$D$27:$D$82) -> 0.031344942 | AH4: ='[4]1982'!$D28/SUM('[4]1982'!$D$27:$D$82) -> 0.031350261 | AI4: ='[4]1983'!$D28/SUM('[4]1983'!$D$27:$D$82) -> 0.031458201 | AJ4: ='[4]1984'!$D28/SUM('[4]1984'!$D$27:$D$82) -> 0.031598507 | AK4: ='[4]1985'!$D28/SUM('[4]1985'!$D$27:$D$82) -> 0.030901866 | AL4: ='[4]1986'!$D28/SUM('[4]1986'!$D$27:$D$82) -> 0.030483003 | AM4: ='[4]1987'!$D28/SUM('[4]1987'!$D$27:$D$82) -> 0.030089523 | AN4: ='[4]1988'!$D28/SUM('[4]1988'!$D$27:$D$82) -> 0.029414674 | AO4: ='[4]1989'!$D28/SUM('[4]1989'!$D$27:$D$82) -> 0.028408463 | AP4: ='[5]us-est90int-09'!$C30/SUM('[5]us-est90int-09'!$C$29:$C$84) -> 0.027328156 | AQ4: ='[5]us-est90int-09'!$C958/SUM('[5]us-est90int-09'!$C$957:$C$1012) -> 0.026656895 | AR4: ='[5]us-est90int-09'!$C2195/SUM('[5]us-est90int-09'!$C$2194:$C$2249) -> 0.025245745 | AS4: ='[5]us-est90int-09'!$C3432/SUM('[5]us-est90int-09'!$C$3431:$C$3486) -> 0.023823019 | AT4: ='[5]us-est90int-09'!$C4669/SUM('[5]us-est90int-09'!$C$4668:$C$4723) -> 0.02325526 | AU4: ='[5]us-est90int-09'!$C5906/SUM('[5]us-est90int-09'!$C$5905:$C$5960) -> 0.023148514 | AV4: ='[5]us-est90int-09'!$C7143/SUM('[5]us-est90int-09'!$C$7142:$C$7197) -> 0.023469935 | AW4: ='[5]us-est90int-09'!$C8380/SUM('[5]us-est90int-09'!$C$8379:$C$8434) -> 0.024554007 | AX4: ='[5]us-est90int-09'!$C9617/SUM('[5]us-est90int-09'!$C$9616:$C$9671) -> 0.022710914 | AY4: ='[5]us-est90int-09'!$C10854/SUM('[5]us-est90int-09'!$C$10853:$C$10908) -> 0.021604944 | AZ4: =Sheet1!P29/SUM(Sheet1!P$28:P$83) -> 0.019370089 | BA4: =Sheet1!Q29/SUM(Sheet1!Q$28:Q$83) -> 0.017500924 | BB4: =Sheet1!R29/SUM(Sheet1!R$28:R$83) -> 0.016815559 | BC4: =Sheet1!S29/SUM(Sheet1!S$28:S$83) -> 0.017177812 | BD4: =Sheet1!T29/SUM(Sheet1!T$28:T$83) -> 0.017042931 | BE4: =Sheet1!U29/SUM(Sheet1!U$28:U$83) -> 0.016807238 | BF4: =Sheet1!V29/SUM(Sheet1!V$28:V$83) -> 0.017806582 | BG4: =Sheet1!W29/SUM(Sheet1!W$28:W$83) -> 0.017500054 | ... BS4: =Sheet1!AI29/SUM(Sheet1!AI$28:AI$83) -> 0.016878975
A5: 27 | B5: ='[1]1950'!$B37/SUM('[1]1950'!$B$35:$B$90) -> 0.028760374 | C5: ='[1]1951'!$B37/SUM('[1]1951'!$B$35:$B$90) -> 0.028729391 | D5: ='[1]1952'!$B37/SUM('[1]1952'!$B$35:$B$90) -> 0.02821216 | E5: ='[1]1953'!$B37/SUM('[1]1953'!$B$35:$B$90) -> 0.027172905 | F5: ='[1]1954'!$B37/SUM('[1]1954'!$B$35:$B$90) -> 0.026650421 | G5: ='[1]1955'!$B37/SUM('[1]1955'!$B$35:$B$90) -> 0.026217261 | H5: ='[1]1956'!$B37/SUM('[1]1956'!$B$35:$B$90) -> 0.025143301 | I5: ='[1]1957'!$B37/SUM('[1]1957'!$B$35:$B$90) -> 0.0248197 | J5: ='[1]1958'!$B37/SUM('[1]1958'!$B$35:$B$90) -> 0.024261851 | K5: ='[1]1959'!$B37/SUM('[1]1959'!$B$35:$B$90) -> 0.02312438 | L5: ='[2]1961'!$B37/SUM('[2]1961'!$B$35:$B$90) -> 0.022421928 | M5: ='[2]1962'!$B37/SUM('[2]1962'!$B$35:$B$90) -> 0.021790787 | N5: ='[2]1963'!$B37/SUM('[2]1963'!$B$35:$B$90) -> 0.022268159 | O5: ='[2]1964'!$B37/SUM('[2]1964'!$B$35:$B$90) -> 0.022112197 | P5: ='[2]1965'!$B37/SUM('[2]1965'!$B$35:$B$90) -> 0.02219435 | Q5: ='[2]1966'!$B37/SUM('[2]1966'!$B$35:$B$90) -> 0.022766412 | R5: ='[2]1967'!$B37/SUM('[2]1967'!$B$35:$B$90) -> 0.022896738 | S5: ='[2]1968'!$B37/SUM('[2]1968'!$B$35:$B$90) -> 0.023068752 | T5: ='[2]1969'!$B37/SUM('[2]1969'!$B$35:$B$90) -> 0.024083635 | U5: ='[2]1969'!$B37/SUM('[2]1969'!$B$35:$B$90) -> 0.024083635 | V5: ='[3]1971'!$B37/SUM('[3]1971'!$B$35:$B$90) -> 0.028204729 | W5: ='[3]1972'!$B37/SUM('[3]1972'!$B$35:$B$90) -> 0.026349027 | X5: ='[3]1973'!$B37/SUM('[3]1973'!$B$35:$B$90) -> 0.025401447 | Y5: ='[3]1974'!$B37/SUM('[3]1974'!$B$35:$B$90) -> 0.024454854 | Z5: ='[3]1975'!$B37/SUM('[3]1975'!$B$35:$B$90) -> 0.033020116 | AA5: ='[3]1976'!$B37/SUM('[3]1976'!$B$35:$B$90) -> 0.030083658 | AB5: ='[3]1977'!$B37/SUM('[3]1977'!$B$35:$B$90) -> 0.029559175 | AC5: ='[3]1978'!$B37/SUM('[3]1978'!$B$35:$B$90) -> 0.028930479 | AD5: ='[3]1979'!$B37/SUM('[3]1979'!$B$35:$B$90) -> 0.029427436 | AE5: ='[3]1979'!$B37/SUM('[3]1979'!$B$35:$B$90) -> 0.029427436 | AF5: ='[4]1980'!$D29/SUM('[4]1980'!$D$27:$D$82) -> 0.030639998 | AG5: ='[4]1981'!$D29/SUM('[4]1981'!$D$27:$D$82) -> 0.030771999 | AH5: ='[4]1982'!$D29/SUM('[4]1982'!$D$27:$D$82) -> 0.031083211 | AI5: ='[4]1983'!$D29/SUM('[4]1983'!$D$27:$D$82) -> 0.031078237 | AJ5: ='[4]1984'!$D29/SUM('[4]1984'!$D$27:$D$82) -> 0.031189245 | AK5: ='[4]1985'!$D29/SUM('[4]1985'!$D$27:$D$82) -> 0.031330887 | AL5: ='[4]1986'!$D29/SUM('[4]1986'!$D$27:$D$82) -> 0.030644932 | AM5: ='[4]1987'!$D29/SUM('[4]1987'!$D$27:$D$82) -> 0.030216539 | AN5: ='[4]1988'!$D29/SUM('[4]1988'!$D$27:$D$82) -> 0.029847998 | AO5: ='[4]1989'!$D29/SUM('[4]1989'!$D$27:$D$82) -> 0.029169093 | AP5: ='[5]us-est90int-09'!$C31/SUM('[5]us-est90int-09'!$C$29:$C$84) -> 0.027881406 | AQ5: ='[5]us-est90int-09'!$C959/SUM('[5]us-est90int-09'!$C$957:$C$1012) -> 0.02739808 | AR5: ='[5]us-est90int-09'!$C2196/SUM('[5]us-est90int-09'!$C$2194:$C$2249) -> 0.026735489 | AS5: ='[5]us-est90int-09'!$C3433/SUM('[5]us-est90int-09'!$C$3431:$C$3486) -> 0.025412198 | AT5: ='[5]us-est90int-09'!$C4670/SUM('[5]us-est90int-09'!$C$4668:$C$4723) -> 0.02400341 | AU5: ='[5]us-est90int-09'!$C5907/SUM('[5]us-est90int-09'!$C$5905:$C$5960) -> 0.023436963 | AV5: ='[5]us-est90int-09'!$C7144/SUM('[5]us-est90int-09'!$C$7142:$C$7197) -> 0.023342086 | AW5: ='[5]us-est90int-09'!$C8381/SUM('[5]us-est90int-09'!$C$8379:$C$8434) -> 0.023744931 | AX5: ='[5]us-est90int-09'!$C9618/SUM('[5]us-est90int-09'!$C$9616:$C$9671) -> 0.024888876 | AY5: ='[5]us-est90int-09'!$C10855/SUM('[5]us-est90int-09'!$C$10853:$C$10908) -> 0.023079104 | AZ5: =Sheet1!P30/SUM(Sheet1!P$28:P$83) -> 0.020656015 | BA5: =Sheet1!Q30/SUM(Sheet1!Q$28:Q$83) -> 0.017195168 | BB5: =Sheet1!R30/SUM(Sheet1!R$28:R$83) -> 0.017107966 | BC5: =Sheet1!S30/SUM(Sheet1!S$28:S$83) -> 0.017018471 | BD5: =Sheet1!T30/SUM(Sheet1!T$28:T$83) -> 0.017239006 | BE5: =Sheet1!U30/SUM(Sheet1!U$28:U$83) -> 0.017158777 | BF5: =Sheet1!V30/SUM(Sheet1!V$28:V$83) -> 0.017393791 | BG5: =Sheet1!W30/SUM(Sheet1!W$28:W$83) -> 0.017972819 | ... BS5: =Sheet1!AI30/SUM(Sheet1!AI$28:AI$83) -> 0.017308466
A6: 28 | B6: ='[1]1950'!$B38/SUM('[1]1950'!$B$35:$B$90) -> 0.028077276 | C6: ='[1]1951'!$B38/SUM('[1]1951'!$B$35:$B$90) -> 0.026908358 | D6: ='[1]1952'!$B38/SUM('[1]1952'!$B$35:$B$90) -> 0.027038689 | E6: ='[1]1953'!$B38/SUM('[1]1953'!$B$35:$B$90) -> 0.026675856 | F6: ='[1]1954'!$B38/SUM('[1]1954'!$B$35:$B$90) -> 0.025847132 | G6: ='[1]1955'!$B38/SUM('[1]1955'!$B$35:$B$90) -> 0.025480781 | H6: ='[1]1956'!$B38/SUM('[1]1956'!$B$35:$B$90) -> 0.02522876 | I6: ='[1]1957'!$B38/SUM('[1]1957'!$B$35:$B$90) -> 0.024348318 | J6: ='[1]1958'!$B38/SUM('[1]1958'!$B$35:$B$90) -> 0.024174128 | K6: ='[1]1959'!$B38/SUM('[1]1959'!$B$35:$B$90) -> 0.023745062 | L6: ='[2]1961'!$B38/SUM('[2]1961'!$B$35:$B$90) -> 0.023042356 | M6: ='[2]1962'!$B38/SUM('[2]1962'!$B$35:$B$90) -> 0.022299257 | N6: ='[2]1963'!$B38/SUM('[2]1963'!$B$35:$B$90) -> 0.021680151 | O6: ='[2]1964'!$B38/SUM('[2]1964'!$B$35:$B$90) -> 0.022125476 | P6: ='[2]1965'!$B38/SUM('[2]1965'!$B$35:$B$90) -> 0.021954894 | Q6: ='[2]1966'!$B38/SUM('[2]1966'!$B$35:$B$90) -> 0.022039488 | R6: ='[2]1967'!$B38/SUM('[2]1967'!$B$35:$B$90) -> 0.022544965 | S6: ='[2]1968'!$B38/SUM('[2]1968'!$B$35:$B$90) -> 0.022639115 | T6: ='[2]1969'!$B38/SUM('[2]1969'!$B$35:$B$90) -> 0.022719497 | U6: ='[2]1969'!$B38/SUM('[2]1969'!$B$35:$B$90) -> 0.022719497 | V6: ='[3]1971'!$B38/SUM('[3]1971'!$B$35:$B$90) -> 0.02498322 | W6: ='[3]1972'!$B38/SUM('[3]1972'!$B$35:$B$90) -> 0.028282211 | X6: ='[3]1973'!$B38/SUM('[3]1973'!$B$35:$B$90) -> 0.026374101 | Y6: ='[3]1974'!$B38/SUM('[3]1974'!$B$35:$B$90) -> 0.025691449 | Z6: ='[3]1975'!$B38/SUM('[3]1975'!$B$35:$B$90) -> 0.024937206 | AA6: ='[3]1976'!$B38/SUM('[3]1976'!$B$35:$B$90) -> 0.033889435 | AB6: ='[3]1977'!$B38/SUM('[3]1977'!$B$35:$B$90) -> 0.031066333 | AC6: ='[3]1978'!$B38/SUM('[3]1978'!$B$35:$B$90) -> 0.030755353 | AD6: ='[3]1979'!$B38/SUM('[3]1979'!$B$35:$B$90) -> 0.030288273 | AE6: ='[3]1979'!$B38/SUM('[3]1979'!$B$35:$B$90) -> 0.030288273 | AF6: ='[4]1980'!$D30/SUM('[4]1980'!$D$27:$D$82) -> 0.028904821 | AG6: ='[4]1981'!$D30/SUM('[4]1981'!$D$27:$D$82) -> 0.028939648 | AH6: ='[4]1982'!$D30/SUM('[4]1982'!$D$27:$D$82) -> 0.028999558 | AI6: ='[4]1983'!$D30/SUM('[4]1983'!$D$27:$D$82) -> 0.029248986 | AJ6: ='[4]1984'!$D30/SUM('[4]1984'!$D$27:$D$82) -> 0.029225435 | AK6: ='[4]1985'!$D30/SUM('[4]1985'!$D$27:$D$82) -> 0.02929598 | AL6: ='[4]1986'!$D30/SUM('[4]1986'!$D$27:$D$82) -> 0.029385605 | AM6: ='[4]1987'!$D30/SUM('[4]1987'!$D$27:$D$82) -> 0.028710492 | AN6: ='[4]1988'!$D30/SUM('[4]1988'!$D$27:$D$82) -> 0.028297138 | AO6: ='[4]1989'!$D30/SUM('[4]1989'!$D$27:$D$82) -> 0.027920551 | AP6: ='[5]us-est90int-09'!$C32/SUM('[5]us-est90int-09'!$C$29:$C$84) -> 0.026973383 | AQ6: ='[5]us-est90int-09'!$C960/SUM('[5]us-est90int-09'!$C$957:$C$1012) -> 0.026899446 | AR6: ='[5]us-est90int-09'!$C2197/SUM('[5]us-est90int-09'!$C$2194:$C$2249) -> 0.026019243 | AS6: ='[5]us-est90int-09'!$C3434/SUM('[5]us-est90int-09'!$C$3431:$C$3486) -> 0.025552633 | AT6: ='[5]us-est90int-09'!$C4671/SUM('[5]us-est90int-09'!$C$4668:$C$4723) -> 0.024378935 | AU6: ='[5]us-est90int-09'!$C5908/SUM('[5]us-est90int-09'!$C$5905:$C$5960) -> 0.023108253 | AV6: ='[5]us-est90int-09'!$C7145/SUM('[5]us-est90int-09'!$C$7142:$C$7197) -> 0.022652717 | AW6: ='[5]us-est90int-09'!$C8382/SUM('[5]us-est90int-09'!$C$8379:$C$8434) -> 0.022708942 | AX6: ='[5]us-est90int-09'!$C9619/SUM('[5]us-est90int-09'!$C$9616:$C$9671) -> 0.02322652 | AY6: ='[5]us-est90int-09'!$C10856/SUM('[5]us-est90int-09'!$C$10853:$C$10908) -> 0.024456659 | AZ6: =Sheet1!P31/SUM(Sheet1!P$28:P$83) -> 0.021531303 | BA6: =Sheet1!Q31/SUM(Sheet1!Q$28:Q$83) -> 0.018012251 | BB6: =Sheet1!R31/SUM(Sheet1!R$28:R$83) -> 0.017149738 | BC6: =Sheet1!S31/SUM(Sheet1!S$28:S$83) -> 0.017308654 | BD6: =Sheet1!T31/SUM(Sheet1!T$28:T$83) -> 0.016976707 | BE6: =Sheet1!U31/SUM(Sheet1!U$28:U$83) -> 0.016967419 | BF6: =Sheet1!V31/SUM(Sheet1!V$28:V$83) -> 0.017444605 | BG6: =Sheet1!W31/SUM(Sheet1!W$28:W$83) -> 0.017199722 | ... BS6: =Sheet1!AI31/SUM(Sheet1!AI$28:AI$83) -> 0.017909752
A7: 29 | B7: ='[1]1950'!$B39/SUM('[1]1950'!$B$35:$B$90) -> 0.028100553 | C7: ='[1]1951'!$B39/SUM('[1]1951'!$B$35:$B$90) -> 0.028042345 | D7: ='[1]1952'!$B39/SUM('[1]1952'!$B$35:$B$90) -> 0.026821431 | E7: ='[1]1953'!$B39/SUM('[1]1953'!$B$35:$B$90) -> 0.026865337 | F7: ='[1]1954'!$B39/SUM('[1]1954'!$B$35:$B$90) -> 0.026447977 | G7: ='[1]1955'!$B39/SUM('[1]1955'!$B$35:$B$90) -> 0.025553979 | H7: ='[1]1956'!$B39/SUM('[1]1956'!$B$35:$B$90) -> 0.025149617 | I7: ='[1]1957'!$B39/SUM('[1]1957'!$B$35:$B$90) -> 0.024851545 | J7: ='[1]1958'!$B39/SUM('[1]1958'!$B$35:$B$90) -> 0.023932264 | K7: ='[1]1959'!$B39/SUM('[1]1959'!$B$35:$B$90) -> 0.02368434 | L7: ='[2]1961'!$B39/SUM('[2]1961'!$B$35:$B$90) -> 0.023660164 | M7: ='[2]1962'!$B39/SUM('[2]1962'!$B$35:$B$90) -> 0.023201078 | N7: ='[2]1963'!$B39/SUM('[2]1963'!$B$35:$B$90) -> 0.022597059 | O7: ='[2]1964'!$B39/SUM('[2]1964'!$B$35:$B$90) -> 0.022069381 | P7: ='[2]1965'!$B39/SUM('[2]1965'!$B$35:$B$90) -> 0.022640836 | Q7: ='[2]1966'!$B39/SUM('[2]1966'!$B$35:$B$90) -> 0.022599631 | R7: ='[2]1967'!$B39/SUM('[2]1967'!$B$35:$B$90) -> 0.022763221 | S7: ='[2]1968'!$B39/SUM('[2]1968'!$B$35:$B$90) -> 0.02338482 | T7: ='[2]1969'!$B39/SUM('[2]1969'!$B$35:$B$90) -> 0.023529431 | U7: ='[2]1969'!$B39/SUM('[2]1969'!$B$35:$B$90) -> 0.023529431 | V7: ='[3]1971'!$B39/SUM('[3]1971'!$B$35:$B$90) -> 0.024711651 | W7: ='[3]1972'!$B39/SUM('[3]1972'!$B$35:$B$90) -> 0.025958948 | X7: ='[3]1973'!$B39/SUM('[3]1973'!$B$35:$B$90) -> 0.028901988 | Y7: ='[3]1974'!$B39/SUM('[3]1974'!$B$35:$B$90) -> 0.026867711 | Z7: ='[3]1975'!$B39/SUM('[3]1975'!$B$35:$B$90) -> 0.026032053 | AA7: ='[3]1976'!$B39/SUM('[3]1976'!$B$35:$B$90) -> 0.025105792 | AB7: ='[3]1977'!$B39/SUM('[3]1977'!$B$35:$B$90) -> 0.033842047 | AC7: ='[3]1978'!$B39/SUM('[3]1978'!$B$35:$B$90) -> 0.030861589 | AD7: ='[3]1979'!$B39/SUM('[3]1979'!$B$35:$B$90) -> 0.030344639 | AE7: ='[3]1979'!$B39/SUM('[3]1979'!$B$35:$B$90) -> 0.030344639 | AF7: ='[4]1980'!$D31/SUM('[4]1980'!$D$27:$D$82) -> 0.029509809 | AG7: ='[4]1981'!$D31/SUM('[4]1981'!$D$27:$D$82) -> 0.030537924 | AH7: ='[4]1982'!$D31/SUM('[4]1982'!$D$27:$D$82) -> 0.030611269 | AI7: ='[4]1983'!$D31/SUM('[4]1983'!$D$27:$D$82) -> 0.030737762 | AJ7: ='[4]1984'!$D31/SUM('[4]1984'!$D$27:$D$82) -> 0.031099057 | AK7: ='[4]1985'!$D31/SUM('[4]1985'!$D$27:$D$82) -> 0.031147036 | AL7: ='[4]1986'!$D31/SUM('[4]1986'!$D$27:$D$82) -> 0.03131315 | AM7: ='[4]1987'!$D31/SUM('[4]1987'!$D$27:$D$82) -> 0.03150379 | AN7: ='[4]1988'!$D31/SUM('[4]1988'!$D$27:$D$82) -> 0.030877183 | AO7: ='[4]1989'!$D31/SUM('[4]1989'!$D$27:$D$82) -> 0.030536779 | AP7: ='[5]us-est90int-09'!$C33/SUM('[5]us-est90int-09'!$C$29:$C$84) -> 0.029985237 | AQ7: ='[5]us-est90int-09'!$C961/SUM('[5]us-est90int-09'!$C$957:$C$1012) -> 0.028506749 | AR7: ='[5]us-est90int-09'!$C2198/SUM('[5]us-est90int-09'!$C$2194:$C$2249) -> 0.029144594 | AS7: ='[5]us-est90int-09'!$C3435/SUM('[5]us-est90int-09'!$C$3431:$C$3486) -> 0.027978722 | AT7: ='[5]us-est90int-09'!$C4672/SUM('[5]us-est90int-09'!$C$4668:$C$4723) -> 0.027180523 | AU7: ='[5]us-est90int-09'!$C5909/SUM('[5]us-est90int-09'!$C$5905:$C$5960) -> 0.025660496 | AV7: ='[5]us-est90int-09'!$C7146/SUM('[5]us-est90int-09'!$C$7142:$C$7197) -> 0.024078904 | AW7: ='[5]us-est90int-09'!$C8383/SUM('[5]us-est90int-09'!$C$8379:$C$8434) -> 0.023420571 | AX7: ='[5]us-est90int-09'!$C9620/SUM('[5]us-est90int-09'!$C$9616:$C$9671) -> 0.023276441 | AY7: ='[5]us-est90int-09'!$C10857/SUM('[5]us-est90int-09'!$C$10853:$C$10908) -> 0.023590326 | AZ7: =Sheet1!P32/SUM(Sheet1!P$28:P$83) -> 0.022999214 | BA7: =Sheet1!Q32/SUM(Sheet1!Q$28:Q$83) -> 0.018874872 | BB7: =Sheet1!R32/SUM(Sheet1!R$28:R$83) -> 0.017442145 | BC7: =Sheet1!S32/SUM(Sheet1!S$28:S$83) -> 0.017074176 | BD7: =Sheet1!T32/SUM(Sheet1!T$28:T$83) -> 0.016990991 | BE7: =Sheet1!U32/SUM(Sheet1!U$28:U$83) -> 0.016600829 | BF7: =Sheet1!V32/SUM(Sheet1!V$28:V$83) -> 0.017098866 | BG7: =Sheet1!W32/SUM(Sheet1!W$28:W$83) -> 0.01694444 | ... BS7: =Sheet1!AI32/SUM(Sheet1!AI$28:AI$83) -> 0.01818755
A8: 30 | B8: ='[1]1950'!$B40/SUM('[1]1950'!$B$35:$B$90) -> 0.027624931 | C8: ='[1]1951'!$B40/SUM('[1]1951'!$B$35:$B$90) -> 0.028182496 | D8: ='[1]1952'!$B40/SUM('[1]1952'!$B$35:$B$90) -> 0.028113246 | E8: ='[1]1953'!$B40/SUM('[1]1953'!$B$35:$B$90) -> 0.026850541 | F8: ='[1]1954'!$B40/SUM('[1]1954'!$B$35:$B$90) -> 0.026882026 | G8: ='[1]1955'!$B40/SUM('[1]1955'!$B$35:$B$90) -> 0.026432829 | H8: ='[1]1956'!$B40/SUM('[1]1956'!$B$35:$B$90) -> 0.025537133 | I8: ='[1]1957'!$B40/SUM('[1]1957'!$B$35:$B$90) -> 0.025124683 | J8: ='[1]1958'!$B40/SUM('[1]1958'!$B$35:$B$90) -> 0.024808579 | K8: ='[1]1959'!$B40/SUM('[1]1959'!$B$35:$B$90) -> 0.023852738 | L8: ='[2]1961'!$B40/SUM('[2]1961'!$B$35:$B$90) -> 0.023872002 | M8: ='[2]1962'!$B40/SUM('[2]1962'!$B$35:$B$90) -> 0.023347869 | N8: ='[2]1963'!$B40/SUM('[2]1963'!$B$35:$B$90) -> 0.022786558 | O8: ='[2]1964'!$B40/SUM('[2]1964'!$B$35:$B$90) -> 0.022047191 | P8: ='[2]1965'!$B40/SUM('[2]1965'!$B$35:$B$90) -> 0.021407543 | Q8: ='[2]1966'!$B40/SUM('[2]1966'!$B$35:$B$90) -> 0.021851703 | R8: ='[2]1967'!$B40/SUM('[2]1967'!$B$35:$B$90) -> 0.021650023 | S8: ='[2]1968'!$B40/SUM('[2]1968'!$B$35:$B$90) -> 0.021660978 | T8: ='[2]1969'!$B40/SUM('[2]1969'!$B$35:$B$90) -> 0.022056128 | U8: ='[2]1969'!$B40/SUM('[2]1969'!$B$35:$B$90) -> 0.022056128 | V8: ='[3]1971'!$B40/SUM('[3]1971'!$B$35:$B$90) -> 0.022233041 | W8: ='[3]1972'!$B40/SUM('[3]1972'!$B$35:$B$90) -> 0.023310201 | X8: ='[3]1973'!$B40/SUM('[3]1973'!$B$35:$B$90) -> 0.024316953 | Y8: ='[3]1974'!$B40/SUM('[3]1974'!$B$35:$B$90) -> 0.027227297 | Z8: ='[3]1975'!$B40/SUM('[3]1975'!$B$35:$B$90) -> 0.025388559 | AA8: ='[3]1976'!$B40/SUM('[3]1976'!$B$35:$B$90) -> 0.02465644 | AB8: ='[3]1977'!$B40/SUM('[3]1977'!$B$35:$B$90) -> 0.023816319 | AC8: ='[3]1978'!$B40/SUM('[3]1978'!$B$35:$B$90) -> 0.03219844 | AD8: ='[3]1979'!$B40/SUM('[3]1979'!$B$35:$B$90) -> 0.02941688 | AE8: ='[3]1979'!$B40/SUM('[3]1979'!$B$35:$B$90) -> 0.02941688 | AF8: ='[4]1980'!$D32/SUM('[4]1980'!$D$27:$D$82) -> 0.029041647 | AG8: ='[4]1981'!$D32/SUM('[4]1981'!$D$27:$D$82) -> 0.028816733 | AH8: ='[4]1982'!$D32/SUM('[4]1982'!$D$27:$D$82) -> 0.029744003 | AI8: ='[4]1983'!$D32/SUM('[4]1983'!$D$27:$D$82) -> 0.029769926 | AJ8: ='[4]1984'!$D32/SUM('[4]1984'!$D$27:$D$82) -> 0.029862598 | AK8: ='[4]1985'!$D32/SUM('[4]1985'!$D$27:$D$82) -> 0.030171932 | AL8: ='[4]1986'!$D32/SUM('[4]1986'!$D$27:$D$82) -> 0.030192871 | AM8: ='[4]1987'!$D32/SUM('[4]1987'!$D$27:$D$82) -> 0.030280397 | AN8: ='[4]1988'!$D32/SUM('[4]1988'!$D$27:$D$82) -> 0.030422001 | AO8: ='[4]1989'!$D32/SUM('[4]1989'!$D$27:$D$82) -> 0.029793368 | AP8: ='[5]us-est90int-09'!$C34/SUM('[5]us-est90int-09'!$C$29:$C$84) -> 0.029218411 | AQ8: ='[5]us-est90int-09'!$C962/SUM('[5]us-est90int-09'!$C$957:$C$1012) -> 0.030243507 | AR8: ='[5]us-est90int-09'!$C2199/SUM('[5]us-est90int-09'!$C$2194:$C$2249) -> 0.027904178 | AS8: ='[5]us-est90int-09'!$C3436/SUM('[5]us-est90int-09'!$C$3431:$C$3486) -> 0.02874336 | AT8: ='[5]us-est90int-09'!$C4673/SUM('[5]us-est90int-09'!$C$4668:$C$4723) -> 0.027735679 | AU8: ='[5]us-est90int-09'!$C5910/SUM('[5]us-est90int-09'!$C$5905:$C$5960) -> 0.027071524 | AV8: ='[5]us-est90int-09'!$C7147/SUM('[5]us-est90int-09'!$C$7142:$C$7197) -> 0.025695113 | AW8: ='[5]us-est90int-09'!$C8384/SUM('[5]us-est90int-09'!$C$8379:$C$8434) -> 0.024307289 | AX8: ='[5]us-est90int-09'!$C9621/SUM('[5]us-est90int-09'!$C$9616:$C$9671) -> 0.023812126 | AY8: ='[5]us-est90int-09'!$C10858/SUM('[5]us-est90int-09'!$C$10853:$C$10908) -> 0.023826938 | AZ8: =Sheet1!P33/SUM(Sheet1!P$28:P$83) -> 0.023137622 | BA8: =Sheet1!Q33/SUM(Sheet1!Q$28:Q$83) -> 0.021440616 | BB8: =Sheet1!R33/SUM(Sheet1!R$28:R$83) -> 0.019889433 | BC8: =Sheet1!S33/SUM(Sheet1!S$28:S$83) -> 0.018763457 | BD8: =Sheet1!T33/SUM(Sheet1!T$28:T$83) -> 0.017776589 | BE8: =Sheet1!U33/SUM(Sheet1!U$28:U$83) -> 0.017856481 | BF8: =Sheet1!V33/SUM(Sheet1!V$28:V$83) -> 0.017988357 | BG8: =Sheet1!W33/SUM(Sheet1!W$28:W$83) -> 0.017949517 | ... BS8: =Sheet1!AI33/SUM(Sheet1!AI$28:AI$83) -> 0.018535255
